Workbook

Sheet คำขอปึ70
B1: =(18990)*105% -> 19939.5 | C1: =80000/6 -> 13333.333 | D1: สรุปรายละเอียดคำขอตั้งงบประมาณของฝ่ายรักษาความปลอดภัย ประจำปี 2570 - สิ้นสุด
D3: รหัสงบฯ | E3: File ประกอบ | F3: ชื่องบประมาณ/ชื่อบัญชี | H3: คำนิยาม | L3: งบปี 2569 | O3: คำขอปี 2570 ( เพิ่มขึ้น / ลดลง ) | T3: คำขอปี 2571 - สิ้นสุดแผนงาน
L4: งบที่ได้ปี 69 +จัดสรรระหว่างปี | M4: ใช้ไป ณ 31 ก.ค. 69 | N4: %ใช้ไป ปี 2569 | O4: งบปี 2570 | P4: เทียบกับ ปี 2569 | Q4: % เทียบกับ ปี 2569 | R4: เปลี่ยนแปลง | S4: เหตุผล | T4: หน่วย | U4: จำนวนเงิน
D5: 1. หมวดค่าใช้จ่าย | L5: =SUM(L6,L9:L14,L20,L23,L27:L31,L36:L39) -> 79578400 | M5: =SUM(M6,M9:M14,M20,M23,M27:M31,M36:M39) -> 36603717 | N5: =IFERROR(M5/L5,1) -> 0.45997051 | O5: =SUM(O6,O9:O14,O20,O23,O27:O31,O36:O39) -> 83730954 | P5: =O5-L5 -> 4152554.4 | Q5: =IFERROR(O5/L5-1,1) -> 0.052181928 | R5: =IF(O5>L5,"เพิ่มขึ้น",IF(O5<L5,"ลดลง",IF(O5=L5,"--"))) -> เพิ่มขึ้น | S5: เพิ่มจาก ค่าเสื้อผ้าฯ + ค่าจ้างสัญญาใหม่กลุ่ม 1 เริ่ม 1 พ.ค.70 + งบวัสดุเกี่ยวกับระงับเหตุ เป็นสำคัญ | T5: =SUM(T14,T23,T37,T38) -> 12 | U5: =SUM(U6,U9:U14,U20,U23,U27:U31,U36:U39) -> 103563190
D6: -- | F6: 1. ค่าตอบแทนการทำงานนอกเวลา | H6: มี 2 ส่วน ดังนี้ | L6: =SUM(L7:L8) -> 5950000 | M6: =SUM(M7:M8) -> 3752559.2 | N6: =IFERROR(M6/L6,1) -> 0.63068222 | O6: =SUM(O7:O8) -> 7090000 | P6: =O6-L6 -> 1140000 | Q6: =IFERROR(O6/L6-1,1) -> 0.19159664 | R6: =IF(O6>L6,"เพิ่มขึ้น",IF(O6<L6,"ลดลง",IF(O6=L6,"--"))) -> เพิ่มขึ้น | S6: เพิ่มทั้งหมวด OT + ศปภ. เข้าเวร ดังนี้ | T6: - | U6: 0
C7: ok | D7: 5020102000 | E7: A1-1 | G7: 1.1 ค่าล่วงเวลาและค่าตอบแทนการทำงานเกินเวลา | H7: 1.-ฝรภ.ปฏิบัติงานแทน OS หยุดงาน+เกิดเหตุไม่ปกติ -ศสป. ศอก. สนับสนุนงาน ศปภ. วันหยุด+นอกเวลางาน -ฝรภ. ปฏิบัติงานเร่งด่วน วันหยุด+นอกเวลางาน | L7: ='สรุปใช้งบ 31กค'!H11 -> 310000 | M7: ='สรุปใช้งบ 31กค'!L11 -> 263759.21 | N7: =IFERROR(M7/L7,1) -> 0.85083616 | O7: =[1]คำขอ2570!$F$8 -> 890000 | P7: =O7-L7 -> 580000 | Q7: =IFERROR(O7/L7-1,1) -> 1.8709677 | R7: =IF(O7>L7,"เพิ่มขึ้น",IF(O7<L7,"ลดลง",IF(O7=L7,"--"))) -> เพิ่มขึ้น | S7: 1.-ศปภ. ปรับการปฏิบัติงานให้สอดคล้อง กม.ใหม่ (หารือ ฝกม.แล้ว) -ศอก. ศสป. ตั้งเพิ่มจากเหตุปฏิบัติงานแทน OS เหตุบอกเลิกสัญญาปี 69 และสำรองงานเร่งด่วนนอกเวลา | T7: - | U7: 0
B8: มีปรับตาราง | C8: ok | D8: 5020104000 | E8: A1-2 | G8: 1.2 เงินช่วยเหลือพิเศษ | H8: 2. ค่าเข้าเวร นอกเวลาปกติ/ วันหยุด | L8: ='สรุปใช้งบ 31กค'!H12 -> 5640000 | M8: ='สรุปใช้งบ 31กค'!L12 -> 3488800 | N8: =IFERROR(M8/L8,1) -> 0.61858156 | O8: ='[2]2570new'!$D$21 -> 6200000 | P8: =O8-L8 -> 560000 | Q8: =IFERROR(O8/L8-1,1) -> 0.09929078 | R8: =IF(O8>L8,"เพิ่มขึ้น",IF(O8<L8,"ลดลง",IF(O8=L8,"--"))) -> เพิ่มขึ้น | S8: 2.-อัตรากำลังลดลงจากปีก่อน 108 >> 103 คน -90% เป็น พนง.เก่าจึงต้องปรับฐานเงินเดือนเฉลี่ยเพิ่มอีก 2.5% เพื่อให้พอต่อการใช้จ่ายปี 70 | T8: - | U8: 0
B9: เอกสารแนบ สีแดง สงสัย | D9: 5020305000 | E9: A2 | F9: 2. เงินช่วยเหลืออื่น ๆ (ปฏิบัติงานต่าง สนง.) | H9: 1. ค่าจัดซื้อของเหมาจ่าย (ให้ครั้งเดียว และเมื่อย้าย) 2. บ้านพัก/ค่าเช่าบ้าน @ 8,000/เดือน 3. เงินช่วยเหลือพิเศษ @ 5,500/เดือน | L9: ='สรุปใช้งบ 31กค'!H13 -> 6650000 | M9: ='สรุปใช้งบ 31กค'!$L$13 -> 2100323.9 | N9: =IFERROR(M9/L9,1) -> 0.31583817 | O9: ='[3]1. ต่างสำนักงาน Rate ปี 70'!$F$20 -> 4380000 | P9: =O9-L9 -> -2270000 | Q9: =IFERROR(O9/L9-1,1) -> -0.34135338 | R9: =IF(O9>L9,"เพิ่มขึ้น",IF(O9<L9,"ลดลง",IF(O9=L9,"--"))) -> ลดลง | S9: -อัตรากำลังลดลงจาก 108 >> 103 คน -ปี 70 ศปภ.ครบวงรอบย้ายลดลง | T9: - | U9: 0
B10: รอราคา | D10: 5020304000 | E10: A3-1 | F10: 3.1 ค่าเสื้อผ้าและเครื่องแบบ | H10: แจก ชุดปฏิบัติการ / ชุดพิธีการ (พนง.เก่า 2 ชุด /พนง.ใหม่ 3 ชุด) | L10: ='สรุปใช้งบ 31กค'!H14 -> 457900 | M10: ='สรุปใช้งบ 31กค'!$L$14 -> 443910.8 | N10: =IFERROR(M10/L10,1) -> 0.96944922 | O10: 1204490 | P10: =O10-L10 -> 746590 | Q10: =IFERROR(O10/L10-1,1) -> 1.6304652 | R10: =IF(O10>L10,"เพิ่มขึ้น",IF(O10<L10,"ลดลง",IF(O10=L10,"--"))) -> เพิ่มขึ้น | S10: -เสื้อผ้าปรับราคาเพิ่มขึ้นมากต้องสืบราคาใหม่ -ปีก่อนๆใช้ราคามาตรฐานจาก ฝผง. ตั้งงบ ซึ่งประกาศมาตั้งแต่ปี 66 -ปี 70 จัดหาชุดพิธีการใหม่ในภาพรวมทั้งหมด -พนง.ใหม่ จัดหา 3 ชุด (ชุดพิธีการ 1 ชุด/ชุดปฏิบัติการ 2 ชุด) | T10: - | U10: 0
C11: ok | D11: 5031207000 | E11: A3-2 | F11: 3.2 ค่าเช่าอุปกรณ์ เครื่องมือ เครื่องใช้ (เช่าชุดสูท) | H11: เช่าชุดสูทปฏิบัติหน้าที่ | L11: 0 | M11: 0 | N11: =IFERROR(M11/L11,1) -> 1 | O11: ='[4]ค่าเช่าชุดสูท 70'!$E$9 -> 50000 | P11: =O11-L11 -> 50000 | Q11: =IFERROR(O11/L11-1,1) -> 1 | R11: =IF(O11>L11,"เพิ่มขึ้น",IF(O11<L11,"ลดลง",IF(O11=L11,"--"))) -> เพิ่มขึ้น | S11: ปี 70 เปลี่ยนวิธีจากเดิมตั้งงบค่าเสื้อผ้าเพื่อซื้อ/ตัด >เปลี่ยนเป็น> เช่าสูทเมื่อมีออก event ซึ่งทำให้ช่วยลดต้นทุนให้ธนาคารได้มาก | T11: - | U11: 0
C12: ok | D12: 5020306000 | E12: A4 | F12: 4. คชจ.กิจกรรมส่งเสริมค่านิยมร่วมขององค์กร (สคส.) | H12: อัตรากำลัง @1,000.- ตามที่ ฝยว. กำหนด | L12: ='สรุปใช้งบ 31กค'!H15 -> 165000 | M12: ='สรุปใช้งบ 31กค'!$L$15 -> 26800.35 | N12: =IFERROR(M12/L12,1) -> 0.16242636 | O12: ='[5]2570'!$H$13 -> 145000 | P12: =O12-L12 -> -20000 | Q12: =IFERROR(O12/L12-1,1) -> -0.12121212 | R12: =IF(O12>L12,"เพิ่มขึ้น",IF(O12<L12,"ลดลง",IF(O12=L12,"--"))) -> ลดลง | S12: -อัตรากำลังลดลงจาก 165 >> 145 คน (อัตราที่ประกาศ) | T12: - | U12: 0
C13: ok | D13: 5020402000 | E13: A5 | F13: 5. ค่าฝึกอบรมและพัฒนาพนักงาน | H13: งบฝึกอบรมและค่าใช้จ่ายในการเดินทางไปอบรม | L13: ='สรุปใช้งบ 31กค'!H16 -> 1522500 | M13: ='สรุปใช้งบ 31กค'!$L$16 -> 257470.89 | N13: =IFERROR(M13/L13,1) -> 0.1691106 | O13: ='[6]2570'!$H$14 -> 675000 | P13: =O13-L13 -> -847500 | Q13: =IFERROR(O13/L13-1,1) -> -0.55665025 | R13: =IF(O13>L13,"เพิ่มขึ้น",IF(O13<L13,"ลดลง",IF(O13=L13,"--"))) -> ลดลง | S13: -ปี 70 ตั้งงบตามที่่ ฝยบ.แจ้ง ฝรภ. -ตั้งแต่ปี 69 เป็นต้นมา ฝยบ. แจ้งจำนวนงบให้ส่วนงานตั้ง | T13: - | U13: 0 | W13: ปี 71 | X13: ปี72 | Y13: ปี73
C14: ok | D14: 5031116000 | E14: A6-1 (ปี69) | F14: 6. ค่าจ้างงานรักษาความปลอดภัย | H14: ค่าจ้าง OS 5 พื้นที่ทั้วประเทศ ดังนี้ | L14: =SUM(L15:L19) -> 55490000 | M14: =SUM(M15:M19) -> 25990272 | N14: =IFERROR(M14/L14,1) -> 0.46837757 | O14: =SUM(O15:O19) -> 59880600 | P14: =O14-L14 -> 4390600 | Q14: =IFERROR(O14/L14-1,1) -> 0.079124167 | R14: =IF(O14>L14,"เพิ่มขึ้น",IF(O14<L14,"ลดลง",IF(O14=L14,"--"))) -> เพิ่มขึ้น | S14: ทุกกลุ่ม : ปี 69 ราคากลางสืบใหม่ /ปี 70 ราคาตามสัญญาซึ่งถูกกว่าราคากลาง | T14: 5 | U14: =SUM(U15:U19) -> 101283500 | W14: =SUM(W15:W19) -> 57250300 | X14: =SUM(X15:X19) -> 32895600 | Y14: =SUM(Y15:Y19) -> 11137600
H15: 1. กลุ่ม1-สนญ. | L15: =Dataผลพิปี69!U31 -> 25020000 | M15: ='[7]กลุ่ม 1'!$H$25 -> 13844752 | N15: =IFERROR(M15/L15,1) -> 0.55334742 | O15: ='[8]Template OS-2570 '!$AU$10+'[8]Template OS-2570 '!$AU$11+'[8]Template OS-2570 '!$AU$12 -> 30297600 | P15: =O15-L15 -> 5277600 | Q15: =IFERROR(O15/L15-1,1) -> 0.21093525 | R15: =IF(O15>L15,"เพิ่มขึ้น",IF(O15<L15,"ลดลง",IF(O15=L15,"--"))) -> เพิ่มขึ้น | S15: 1.กลุ่ม 1, 5 เพิ่มเนื่องจาก - กลุ่ม 1 ตั้งแต่ ธ.ค. 69 เพิ่ม 0S ห้องควบคุม 4 คน - กลุ่ม 5 ปี 70 สืบราคาเพื่อจัดซื้อใหม่ หลังบอกเลิกสัญญา สูงกว่าราคาปี 69 | T15: 1 | U15: =W15+X15+Y15 -> 76479500 | W15: ='[8]Template OS-2570 '!$AX$12 -> 32446300 | X15: ='[8]Template OS-2570 '!$BA$12 -> 32895600 | Y15: ='[8]Template OS-2570 '!$BD$12 -> 11137600
H16: 2. กลุ่ม2-สภน./ศชม. | L16: =Dataผลพิปี69!U32 -> 6100000 | M16: =[7]กลุ่ม2!$H$43 -> 3041731.3 | N16: =IFERROR(M16/L16,1) -> 0.49864447 | O16: ='[8]Template OS-2570 '!$AU$14 -> 5243500 | P16: =O16-L16 -> -856500 | Q16: =IFERROR(O16/L16-1,1) -> -0.14040984 | R16: =IF(O16>L16,"เพิ่มขึ้น",IF(O16<L16,"ลดลง",IF(O16=L16,"--"))) -> ลดลง | T16: 1 | U16: =W16+X16+Y16 -> 4373000 | W16: ='[8]Template OS-2570 '!$AX$14 -> 4373000
C17: ok | E17: A6-2 (ปี70) | H17: 3. กลุ่ม3-สภอ. | L17: =Dataผลพิปี69!U33 -> 6170000 | M17: =[9]กลุ่ม3!$H$43 -> 1942537.4 | N17: =IFERROR(M17/L17,1) -> 0.31483588 | O17: ='[8]Template OS-2570 '!$AU$18 -> 5458400 | P17: =O17-L17 -> -711600 | Q17: =IFERROR(O17/L17-1,1) -> -0.11533225 | R17: =IF(O17>L17,"เพิ่มขึ้น",IF(O17<L17,"ลดลง",IF(O17=L17,"--"))) -> ลดลง | T17: 1 | U17: =W17+X17+Y17 -> 4688000 | W17: ='[8]Template OS-2570 '!$AX$18 -> 4688000
H18: 4. กลุ่ม4-สภต./ศหญ. ศพง. | L18: =Dataผลพิปี69!U34 -> 6200000 | M18: =[9]กลุ่ม4!$H$43 -> 3452552.2 | N18: =IFERROR(M18/L18,1) -> 0.55686325 | O18: ='[8]Template OS-2570 '!$AU$20 -> 5949500 | P18: =O18-L18 -> -250500 | Q18: =IFERROR(O18/L18-1,1) -> -0.040403226 | R18: =IF(O18>L18,"เพิ่มขึ้น",IF(O18<L18,"ลดลง",IF(O18=L18,"--"))) -> ลดลง | S18: 2. กลุ่ม 2-4 ลดลงเนื่องจาก -กลุ่ม 2, 4 เป็นราคาราคาตามสัญญาซึ่งถูกกว่าราคากลางปี 69 -กลุ่ม 3 ราคาสัญญาหลัง stop gap สืบใหม่เริ่มสัญญาปี 70 ใช้ราคาสัญญา บ.ขอนแก่น +3% | T18: 1 | U18: =W18+X18+Y18 -> 4961200 | W18: ='[8]Template OS-2570 '!$AX$20 -> 4961200
H19: 5. กลุ่ม5-สอบ. ศรย. | L19: =Dataผลพิปี69!U35 -> 12000000 | M19: =[9]กลุ่ม5!$H$53 -> 3708698.3 | N19: =IFERROR(M19/L19,1) -> 0.30905819 | O19: ='[8]Template OS-2570 '!$AU$24 -> 12931600 | P19: =O19-L19 -> 931600 | Q19: =IFERROR(O19/L19-1,1) -> 0.077633333 | R19: =IF(O19>L19,"เพิ่มขึ้น",IF(O19<L19,"ลดลง",IF(O19=L19,"--"))) -> เพิ่มขึ้น | T19: 1 | U19: =W19+X19+Y19 -> 10781800 | W19: ='[8]Template OS-2570 '!$AX$24 -> 10781800
D20: -- | F20: 7. ค่าจ้าง/ค่าตอบแทน | H20: มี 2 ส่วน ดังนี้ | L20: =SUM(L21:L22) -> 4372900 | M20: =SUM(M21:M22) -> 2170381 | N20: =IFERROR(M20/L20,1) -> 0.49632532 | O20: =SUM(O21:O22) -> 4376900 | P20: =O20-L20 -> 4000 | Q20: =IFERROR(O20/L20-1,1) -> 0.00091472478 | R20: =IF(O20>L20,"เพิ่มขึ้น",IF(O20<L20,"ลดลง",IF(O20=L20,"--"))) -> เพิ่มขึ้น | S20: เพิ่มจากค่าจ้างแรงงานทำของ ดังนี้ | T20: - | U20: 0
B21: เอกสารแนบ สีแดง สงสัย | D21: 5031120000 | E21: A7-1 | G21: 7.1 ค่าจ้างแรงงาน/ทำของ-งานทั่วไป | H21: 1. ค่าซ่อมบัตร RFID และ ค่าตรวจสอบเครื่องอัดอากาศช่วยหายใจในการดับเพลิง | L21: ='สรุปใช้งบ 31กค'!$H$18 -> 31000 | M21: ='สรุปใช้งบ 31กค'!$L$18 -> 24931 | N21: =IFERROR(M21/L21,1) -> 0.80422581 | O21: ='[10]2570'!$C$22 -> 35000 | P21: =O21-L21 -> 4000 | Q21: =IFERROR(O21/L21-1,1) -> 0.12903226 | R21: =IF(O21>L21,"เพิ่มขึ้น",IF(O21<L21,"ลดลง",IF(O21=L21,"--"))) -> เพิ่มขึ้น | S21: ทำของ# 1. ตั้งสำรองกรณีฉุกเฉินเพิ่ม เช่น ราคาปรับตัวเพิ่มมาก มีค่าตรวจสอบใหม่ | T21: - | U21: 0
C22: 0k | D22: 5031143000 | E22: A7-2 | G22: 7.2 ค่าตอบแทนบุคคลภายนอกอื่น ๆ | H22: 2. ตร. ช่วยรักษาการณ์ ศปภ. | L22: ='สรุปใช้งบ 31กค'!$H$19 -> 4341900 | M22: ='สรุปใช้งบ 31กค'!$L$19 -> 2145450 | N22: =IFERROR(M22/L22,1) -> 0.494127 | O22: ='[11]2570'!$T$38 -> 4341900 | P22: =O22-L22 -> 0 | Q22: =IFERROR(O22/L22-1,1) -> 0 | R22: =IF(O22>L22,"เพิ่มขึ้น",IF(O22<L22,"ลดลง",IF(O22=L22,"--"))) -> -- | S22: 2. ตั้งตามอัตราที่บันทึกเลขที่ 5/66 กำหนด | T22: - | U22: 0 | W22: ปี 71 | X22: ปี72
C23: ok | D23: 5031214000 | E23: A8 | F23: 8. ค่าซ่อมแซมและบํารุงรักษา - อุปกรณ์และระบบคอมฯ | H23: มี 3 ส่วน ดังนี้ | L23: =SUM(L24:L26) -> 2414500 | M23: =SUM(M24:M26) -> 1205595.8 | N23: =IFERROR(M23/L23,1) -> 0.49931487 | O23: =SUM(O24:O26) -> 1977164.4 | P23: =O23-L23 -> -437335.62 | Q23: =IFERROR(O23/L23-1,1) -> -0.18112886 | R23: =IF(O23>L23,"เพิ่มขึ้น",IF(O23<L23,"ลดลง",IF(O23=L23,"--"))) -> ลดลง | S23: ลดลงทั้ง 2 สัญญาดังนี้ | T23: =SUM(T24:T26) -> 2 | U23: =SUM(U24:U26) -> 2270890 | W23: =SUM(W24:W25) -> 1531662 | X23: =SUM(X24:X25) -> 739228
H24: 1. ค่าซ่อมบำรุง CCTV | L24: 2263100 | M24: 1131525 | N24: =IFERROR(M24/L24,1) -> 0.49998895 | O24: ='[12]new 2570'!$E$7 -> 1844150 | P24: =O24-L24 -> -418950 | Q24: =IFERROR(O24/L24-1,1) -> -0.18512218 | R24: =IF(O24>L24,"เพิ่มขึ้น",IF(O24<L24,"ลดลง",IF(O24=L24,"--"))) -> ลดลง | S24: 1. -ปี 70 = สัญญาใหม่ เฉพาะ สนญ. -ปี 69 =สัญญารวมทั้ง สนญ. + สนภ. 3 แห่ง | T24: 1 | U24: =SUM(W24:X24) -> 2137875 | W24: 1425250 | X24: 712625
H25: 2. จ้างบำรุงรักษาอุปกรณ์ Visitor Management (เครื่องอ่าน บัตรประชาชน, เครื่องอ่าน Passport, เครื่องถ่ายรูปบัตร) | L25: 106500 | M25: 53205.75 | N25: =IFERROR(M25/L25,1) -> 0.49958451 | O25: ='[12]new 2570'!$E$11 -> 133014.38 | P25: =O25-L25 -> 26514.375 | Q25: =IFERROR(O25/L25-1,1) -> 0.24896127 | R25: =IF(O25>L25,"เพิ่มขึ้น",IF(O25<L25,"ลดลง",IF(O25=L25,"--"))) -> เพิ่มขึ้น | S25: 2. -ปี 70 = เพิ่มสัญญาใหม่ต่อเนื่องจากปีปัจจุบัน (สิ้นสุดปี 72) -ปี 69 =สัญญาปัจจุบัน (สิ้นสุดปี 70) | T25: 1 | U25: =SUM(W25:X25) -> 133015 | W25: 106412 | X25: 26603
H26: 3. จ้างบำรุงรักษาเครื่องพิมพ์บัตร Access Card ยี่ห้อ Datacard | L26: 44900 | M26: 20865 | N26: =IFERROR(M26/L26,1) -> 0.46469933 | O26: ='[13]new 2570'!$E$15 -> 0 | P26: =O26-L26 -> -44900 | Q26: =IFERROR(O26/L26-1,1) -> -1 | R26: =IF(O26>L26,"เพิ่มขึ้น",IF(O26<L26,"ลดลง",IF(O26=L26,"--"))) -> ลดลง | S26: 2. ปี 70 ซื้อเครื่องใหม่ ให้มีเงื่อนไขซ่อมบำรุง (ระยะประกัน 3 ปี รวม MA) | T26: - | U26: 0
D27: 5031218000 | E27: A9 | F27: 9. ค่าวัสดุคอมพิวเตอร์ | H27: จัดหาบัตร Mifare /RFID /Access Card (บัตรพนักงาน) | L27: 147000 | M27: 46866 | N27: =IFERROR(M27/L27,1) -> 0.31881633 | O27: ='[14]2570'!$F$16 -> 195000 | P27: =O27-L27 -> 48000 | Q27: =IFERROR(O27/L27-1,1) -> 0.32653061 | R27: =IF(O27>L27,"เพิ่มขึ้น",IF(O27<L27,"ลดลง",IF(O27=L27,"--"))) -> เพิ่มขึ้น | S27: ราคาบัตร RFID เพิ่มขึ้นอย่างมีนัยสำคัญ (860 >> 2,500 บาท) ตั้งตามความต้องการใช้ในแต่ละปี โดยพิจารณา stock ที่มีอยู่ปัจุบันและตั้งให้พอใช้ทั้งปี 70 | T27: - | U27: 0
B28: เอกสารแนบ สีแดง สงสัย | D28: 5031219000 | E28: A10 | F28: 10. ค่าวัสดุทั่วไป | H28: 1.วัสดุในงานห้องบัตร เช่น บัตร RFID 2. วัสดุส่วนกลาง เช่น วัสดุสำนักงาน 3.วัสดุงาน รปภ. เช่น ถังดับเพลิง ผ้าคลุมรถ EV ฯลฯ | L28: ='สรุปใช้งบ 31กค'!H24 -> 305300 | M28: ='สรุปใช้งบ 31กค'!L24 -> 126239.72 | N28: =IFERROR(M28/L28,1) -> 0.41349401 | O28: ='[15]2570'!$E$8 -> 1580000 | P28: =O28-L28 -> 1274700 | Q28: =IFERROR(O28/L28-1,1) -> 4.1752375 | R28: =IF(O28>L28,"เพิ่มขึ้น",IF(O28<L28,"ลดลง",IF(O28=L28,"--"))) -> เพิ่มขึ้น | S28: ESG# มีรายการเพิ่มขึ้นอย่างมีนัยสำคัญดังนี้ -เพิ่มวัสดุเกี่ยวกับการระงับเหตุ EV ประมาณ 400,000.- -อุปกรณ์ห้องบัตร ประมาณ 370,000.- - อุปกรณ์เพื่อยกประสิทธิภาพระงับเหตุ ประมาณ 150,000.- - ถังดับเพลิง ประมาณ 700,000 บาท | T28: - | U28: 0
C29: 0k | D29: 5031138000 | E29: A11 | F29: 11. ค่าใช้จ่ายในการจัดงานและพิธีต่าง ๆ | H29: จัดงาน Financial Crime Investigation | L29: ='สรุปใช้งบ 31กค'!H26 -> 150000 | M29: ='สรุปใช้งบ 31กค'!L26 -> 0 | N29: =IFERROR(M29/L29,1) -> 0 | O29: ='[16]2570'!$D$13 -> 150000 | P29: =O29-L29 -> 0 | Q29: =IFERROR(O29/L29-1,1) -> 0 | R29: =IF(O29>L29,"เพิ่มขึ้น",IF(O29<L29,"ลดลง",IF(O29=L29,"--"))) -> -- | S29: -วางแผนจัด ก.ย.-ต.ค. (ปี 69 จัด 16-18 ก.ย.69) -จัดงานเหมือนปี69 (จัดอบรมซึ่งมีบุคคลภายนอก ไม่สามารถตั้งเป็นงบอบรมได้) | T29: - | U29: 0
C30: 0k | D30: 5031144000 | E30: A12 | F30: 12. ค่ารับรอง | H30: 1. ค่ารับรองของ ผอ. 2. ค่ารับรองของ ศปภ. 5 แห่ง | L30: ='สรุปใช้งบ 31กค'!H27 -> 80000 | M30: ='สรุปใช้งบ 31กค'!L27 -> 24068 | N30: =IFERROR(M30/L30,1) -> 0.30085 | O30: ='[17]2570'!$C$20 -> 80000 | P30: =O30-L30 -> 0 | Q30: =IFERROR(O30/L30-1,1) -> 0 | R30: =IF(O30>L30,"เพิ่มขึ้น",IF(O30<L30,"ลดลง",IF(O30=L30,"--"))) -> -- | S30: จำเป็นต้องสร้าง connection เหมือนเดิม | T30: - | U30: 0
C31: ok | D31: 5031134000 | E31: A13 | F31: 13. ค่าใช้จ่ายเดินทาง | H31: ค่าเบี้ยเลี้ยง ที่พัก และพาหนะเดินทาง มี 5 ส่วน ดังนี้ | L31: =SUM(L32:L35) -> 1597000 | M31: ='สรุปใช้งบ 31กค'!L28 -> 369502.95 | N31: =IFERROR(M31/L31,1) -> 0.23137317 | O31: =SUM(O32:O35) -> 1630000 | P31: =O31-L31 -> 33000 | Q31: =IFERROR(O31/L31-1,1) -> 0.020663745 | R31: =IF(O31>L31,"เพิ่มขึ้น",IF(O31<L31,"ลดลง",IF(O31=L31,"--"))) -> เพิ่มขึ้น | S31: ปรับกระบวนการ ศอก. ใช้คนตรวจน้อยลงเป็นสำคัญ | T31: - | U31: 0
H32: 1. ศปภ.เยี่ยมครอบครัว | L32: =Dataผลพิปี69!U63 -> 460000 | M32: n.a. | N32: =IFERROR(M32/L32,1) -> 1 | O32: ='[18]รวม คชจ.ปี 70'!$C$23 -> 480000 | P32: =O32-L32 -> 20000 | Q32: =IFERROR(O32/L32-1,1) -> 0.043478261 | R32: =IF(O32>L32,"เพิ่มขึ้น",IF(O32<L32,"ลดลง",IF(O32=L32,"--"))) -> เพิ่มขึ้น | S32: ดน.# 1.มีกลุ่มคนประจำต่างสำนักงานมากขึ้น | T32: - | U32: 0
H33: 2. ผู้บริหาร ศปก. / ศอก. เดินทางไปภูมิภาค /หชป.เวียนงาน | L33: =Dataผลพิปี69!U64 -> 587000 | M33: n.a. | N33: =IFERROR(M33/L33,1) -> 1 | O33: ='[18]รวม คชจ.ปี 70'!$C$24 -> 500000 | P33: =O33-L33 -> -87000 | Q33: =IFERROR(O33/L33-1,1) -> -0.14821124 | R33: =IF(O33>L33,"เพิ่มขึ้น",IF(O33<L33,"ลดลง",IF(O33=L33,"--"))) -> ลดลง | S33: ดน.# 2.ศอก./ศปภ. ใช้คนตรวจน้อยลง / ทริป ผอ. ลดลง | T33: - | U33: 0
H34: 3. ศปภ. โยกย้าย | L34: =Dataผลพิปี69!U65 -> 400000 | M34: n.a. | N34: =IFERROR(M34/L34,1) -> 1 | O34: ='[18]รวม คชจ.ปี 70'!$C$24 -> 500000 | P34: =O34-L34 -> 100000 | Q34: =IFERROR(O34/L34-1,1) -> 0.25 | R34: =IF(O34>L34,"เพิ่มขึ้น",IF(O34<L34,"ลดลง",IF(O34=L34,"--"))) -> เพิ่มขึ้น | S34: ดน.# 3.โยกย้ายมากขึ้น เมื่อหลักเกณฑ์ท้องถิ่นออกปีแรก | T34: - | U34: 0
H35: 4. งานสืบสวนและประมวลข่าว | L35: =Dataผลพิปี69!U66 -> 150000 | M35: n.a. | N35: =IFERROR(M35/L35,1) -> 1 | O35: ='[18]รวม คชจ.ปี 70'!$C$26 -> 150000 | P35: =O35-L35 -> 0 | Q35: =IFERROR(O35/L35-1,1) -> 0 | R35: =IF(O35>L35,"เพิ่มขึ้น",IF(O35<L35,"ลดลง",IF(O35=L35,"--"))) -> -- | S35: ดน.# 4. ตั้งเท่าปีก่อน /เพียงพอใช้ | T35: - | U35: 0
C36: ok | D36: 5031107000 | E36: A14 | F36: 14. ค่าธรรมเนียมอื่น ๆ | H36: 1. ค่าความถี่และค่าต่ออายุวิทยุสื่อสาร 2. ใบอนุญาตยุทธภัณฑ์ 3. ค่าตรวจรังสี พนง.รปภ. 7 เครื่อง และ 14 คน 4. ค่าจัดสรรคลื่นความถี่วิทยุ 5. ใบอนุญาตครอบครองเครื่องกำเนิดรังสี | L36: ='สรุปใช้งบ 31กค'!H29 -> 27000 | M36: ='สรุปใช้งบ 31กค'!L29 -> 1177 | N36: =IFERROR(M36/L36,1) -> 0.043592593 | O36: ='[19]2570'!$D$28 -> 40000 | P36: =O36-L36 -> 13000 | Q36: =IFERROR(O36/L36-1,1) -> 0.48148148 | R36: =IF(O36>L36,"เพิ่มขึ้น",IF(O36<L36,"ลดลง",IF(O36=L36,"--"))) -> เพิ่มขึ้น | S36: -ค่าธรรมเนียมใหม่ ได้แก่ ค่าบริการ Internet SIM รายปี สำหรับ Body Camara -สำรองฉุกเฉิน | T36: - | U36: 0 | W36: ปี 71
B37: มีโปรใช้ร่วมกัน | C37: เช็คโปร? | D37: 5031118000 | E37: A15-1 | F37: 15. ค่าสิทธิ์การใช้โปรแกรมส่วนงาน | H37: ใช้โปรแกรม Canva Pro 4 license | L37: ='สรุปใช้งบ 31กค'!H32 -> 6300 | M37: ='สรุปใช้งบ 31กค'!L32 -> 5550 | N37: =IFERROR(M37/L37,1) -> 0.88095238 | O37: ='[20]ค่าสิทธิการใช้โปรแกรม ปี 70'!$H$202 -> 8800 | P37: =O37-L37 -> 2500 | Q37: =IFERROR(O37/L37-1,1) -> 0.3968254 | R37: =IF(O37>L37,"เพิ่มขึ้น",IF(O37<L37,"ลดลง",IF(O37=L37,"--"))) -> เพิ่มขึ้น | S37: DATA# เพิ่ม 1 licence รวมเป็น 4 licence (ศอก. 2, ศสป. 1, ศปภ. 1) | T37: 4 | U37: ='[20]ค่าสิทธิการใช้โปรแกรม ปี 70'!$I$202 -> 8800 | W37: =U37 -> 8800
C38: ok | D38: 5031133000 | E38: A15-2 | F38: 16. ค่าสิทธิ์การใช้โปรแกรมส่วนกลาง | H38: ใช้โปรแกรม Adobe 1 license | L38: ='สรุปใช้งบ 31กค'!H33 -> 23000 | M38: =L38 -> 23000 | N38: =IFERROR(M38/L38,1) -> 1 | O38: ='[21]ค่าสิทธิการใช้โปรแกรม ปี 70'!$H$202 -> 48000 | P38: =O38-L38 -> 25000 | Q38: =IFERROR(O38/L38-1,1) -> 1.0869565 | R38: =IF(O38>L38,"เพิ่มขึ้น",IF(O38<L38,"ลดลง",IF(O38=L38,"--"))) -> เพิ่มขึ้น | S38: DATA# เพิ่ม 1 licence รวมเป็น 2 licence (พนง. 1,OS 1) + ราคาปรับตัวเพิ่ม | T38: 1 | W38: ฝทส. แจ้งไม่ต้องตั้งผูกฟัน
C39: ok | D39: 5031131000 | E39: A16 | F39: 17. ค่าใช้จ่ายในการสืบสวนเกี่ยวกับงาน รปภ. | H39: ใช้สืบสวนของ ทสส.1-2 | L39: ='สรุปใช้งบ 31กค'!H30 -> 220000 | M39: ='สรุปใช้งบ 31กค'!L30 -> 60000 | N39: =IFERROR(M39/L39,1) -> 0.27272727 | O39: ='[22]2570'!$E$7 -> 220000 | P39: =O39-L39 -> 0 | Q39: =IFERROR(O39/L39-1,1) -> 0 | R39: =IF(O39>L39,"เพิ่มขึ้น",IF(O39<L39,"ลดลง",IF(O39=L39,"--"))) -> -- | S39: ตั้งเท่าปีก่อน /เพียงพอใช้ | T39: - | U39: 0
C40: หน่วยงานที่ขอตั้ง | D40: 2. หมวดสินทรัพย์ถาวร | H40: จำนวนปี 69 | I40: ราคา @ ปี 69 | J40: จำนวนปี 70 | K40: ราคา @ ปี 70 | L40: =SUM(L41:L82) -> 29633600 | M40: =SUM(M41:M82) -> 25341985 | N40: =IFERROR(M40/L40,1) -> 0.8551774 | O40: =SUM(O41:O82) -> 26641500 | P40: =O40-L40 -> -2992100 | Q40: =IFERROR(O40/L40-1,1) -> -0.10096985 | R40: =IF(O40>L40,"เพิ่มขึ้น",IF(O40<L40,"ลดลง",IF(O40=L40,"--"))) -> ลดลง | S40: ปี 69 Access Control System รายการเดียวราคาสูงถึง = 13.4 ล้านบาท | U40: =SUM(U41:U82) -> 0
B41: รอแบบขอ / ฝจอ ไม่บวก 10% | C41: ฝจอ ไม่บวกราคา | D41: AUC | E41: B1 | F41: ระบบห้องควบคุม ฝรภ. อาคาร 1 และ 2 (Wall monitor ห้องควบคุม อาคาร 1, 2 และซื้อเครื่อง HDR จำนวน 9 เครื่อง และ work station จำนวน 1 เครื่องห้องควบคุมอาคาร 2) | H41: -- | I41: 0 | J41: 1 | K41: =ROUNDUP(1630894,-4) -> 1640000 | N41: =IFERROR(M41/L41,1) -> 1 | O41: =K41*J41 -> 1640000 | P41: =O41-L41 -> 1640000 | Q41: =IFERROR(O41/L41-1,1) -> 1 | R41: =IF(O41>L41,"เพิ่มขึ้น",IF(O41<L41,"ลดลง",IF(O41=L41,"--"))) -> เพิ่มขึ้น | S41: เป็นการปรับปรุงเพื่อให้รองรับการปฏิบัติงาน OS และการกำกับควบคุม OS ซึ่งผ่านการหารือ ฝจอ. ฝทส. ฝสภ. แล้ว
...

Sheet คำขอปึ70 (หัวข้อแบบเสนอ ผผ)
B1: =(18990)*105% -> 19939.5 | C1: =80000/6 -> 13333.333 | D1: สรุปรายละเอียดคำขอตั้งงบประมาณของฝ่ายรักษาความปลอดภัย ประจำปี 2570 - สิ้นสุด
D3: รหัสงบฯ | E3: File ประกอบ | F3: ชื่องบประมาณ/ชื่อบัญชี | H3: คำนิยาม | L3: งบปี 2569 | O3: คำขอปี 2570 ( เพิ่มขึ้น / ลดลง ) | T3: คำขอปี 2571 - สิ้นสุดแผนงาน
L4: งบที่ได้ปี 69 +จัดสรรระหว่างปี | M4: ใช้ไป ณ 31 ก.ค. 69 | N4: %ใช้ไป ปี 2569 | O4: งบปี 2570 | P4: เทียบกับ ปี 2569 | Q4: % เทียบกับ ปี 2569 | R4: เปลี่ยนแปลง | S4: เหตุผล | T4: หน่วย | U4: จำนวนเงิน
D5: 1. หมวดค่าใช้จ่าย | L5: =SUM(L6,L9:L14,L20,L23,L27:L31,L36:L39) -> 79578400 | M5: =SUM(M6,M9:M14,M20,M23,M27:M31,M36:M39) -> 36603717 | N5: =IFERROR(M5/L5,1) -> 0.45997051 | O5: =SUM(O6,O9:O14,O20,O23,O27:O31,O36:O39) -> 83730954 | P5: =O5-L5 -> 4152554.4 | Q5: =IFERROR(O5/L5-1,1) -> 0.052181928 | R5: =IF(O5>L5,"เพิ่มขึ้น",IF(O5<L5,"ลดลง",IF(O5=L5,"--"))) -> เพิ่มขึ้น | S5: อัตรา ฝรภ. กำลังลดลง /จัดซื้อ OS ได้ราคาถูกลง /MA สนภ.ตั้งงบเอง | T5: =SUM(T14,T23,T37,T38) -> 12 | U5: =SUM(U6,U9:U14,U20,U23,U27:U31,U36:U39) -> 1.0356309e+08
D6: -- | F6: 1. ค่าตอบแทนการทำงานนอกเวลา | H6: มี 2 ส่วน ดังนี้ | L6: =SUM(L7:L8) -> 5950000 | M6: =SUM(M7:M8) -> 3752559.2 | N6: =IFERROR(M6/L6,1) -> 0.63068222 | O6: =SUM(O7:O8) -> 7090000 | P6: =O6-L6 -> 1140000 | Q6: =IFERROR(O6/L6-1,1) -> 0.19159664 | R6: =IF(O6>L6,"เพิ่มขึ้น",IF(O6<L6,"ลดลง",IF(O6=L6,"--"))) -> เพิ่มขึ้น | S6: เพิ่มทั้งหมวด OT + ศปภ. เข้าเวร ดังนี้ | T6: - | U6: 0
C7: ok | D7: 5020102000 | E7: A1-1 | G7: 1.1 ค่าล่วงเวลาและค่าตอบแทนการทำงานเกินเวลา | H7: 1.-ฝรภ.ปฏิบัติงานแทน OS หยุดงาน+เกิดเหตุไม่ปกติ -ศสป. ศอก. สนับสนุนงาน ศปภ. วันหยุด+นอกเวลางาน -ฝรภ. ปฏิบัติงานเร่งด่วน วันหยุด+นอกเวลางาน | L7: ='สรุปใช้งบ 31กค'!H11 -> 310000 | M7: ='สรุปใช้งบ 31กค'!L11 -> 263759.21 | N7: =IFERROR(M7/L7,1) -> 0.85083616 | O7: =[1]คำขอ2570!$F$8 -> 890000 | P7: =O7-L7 -> 580000 | Q7: =IFERROR(O7/L7-1,1) -> 1.8709677 | R7: =IF(O7>L7,"เพิ่มขึ้น",IF(O7<L7,"ลดลง",IF(O7=L7,"--"))) -> เพิ่มขึ้น | S7: 1.-ศปภ. ปรับการปฏิบัติงานให้สอดคล้อง กม.ใหม่ (หารือ ฝกม.แล้ว) -ศอก. ศสป. ตั้งเพิ่มจากเหตุปฏิบัติงานแทน OS เหตุบอกเลิกสัญญาปี 69 และสำรองงานเร่งด่วนนอกเวลา | T7: - | U7: 0
B8: มีปรับตาราง | C8: ok | D8: 5020104000 | E8: A1-2 | G8: 1.2 เงินช่วยเหลือพิเศษ | H8: 2. ค่าเข้าเวร นอกเวลาปกติ/ วันหยุด | L8: ='สรุปใช้งบ 31กค'!H12 -> 5640000 | M8: ='สรุปใช้งบ 31กค'!L12 -> 3488800 | N8: =IFERROR(M8/L8,1) -> 0.61858156 | O8: ='[2]2570new'!$D$21 -> 6200000 | P8: =O8-L8 -> 560000 | Q8: =IFERROR(O8/L8-1,1) -> 0.09929078 | R8: =IF(O8>L8,"เพิ่มขึ้น",IF(O8<L8,"ลดลง",IF(O8=L8,"--"))) -> เพิ่มขึ้น | S8: 2.-อัตรากำลังลดลงจากปีก่อน 108 >> 103 คน -90% เป็น พนง.เก่าจึงต้องปรับฐานเงินเดือนเฉลี่ยเพิ่มอีก 2.5% เพื่อให้พอต่อการใช้จ่ายปี 70 | T8: - | U8: 0
B9: เอกสารแนบ สีแดง สงสัย | D9: 5020305000 | E9: A2 | F9: 2. เงินช่วยเหลืออื่น ๆ (ปฏิบัติงานต่าง สนง.) | H9: 1. ค่าจัดซื้อของเหมาจ่าย (ให้ครั้งเดียว และเมื่อย้าย) 2. บ้านพัก/ค่าเช่าบ้าน @ 8,000/เดือน 3. เงินช่วยเหลือพิเศษ @ 5,500/เดือน | L9: ='สรุปใช้งบ 31กค'!H13 -> 6650000 | M9: ='สรุปใช้งบ 31กค'!$L$13 -> 2100323.9 | N9: =IFERROR(M9/L9,1) -> 0.31583817 | O9: ='[3]1. ต่างสำนักงาน Rate ปี 70'!$F$20 -> 4380000 | P9: =O9-L9 -> -2270000 | Q9: =IFERROR(O9/L9-1,1) -> -0.34135338 | R9: =IF(O9>L9,"เพิ่มขึ้น",IF(O9<L9,"ลดลง",IF(O9=L9,"--"))) -> ลดลง | S9: -อัตรากำลังลดลงจาก 108 >> 103 คน -ปี 70 ศปภ.ครบวงรอบย้ายลดลง | T9: - | U9: 0
B10: รอราคา | D10: 5020304000 | E10: A3-1 | F10: 3.1 ค่าเสื้อผ้าและเครื่องแบบ | H10: แจก ชุดปฏิบัติการ / ชุดพิธีการ (พนง.เก่า 2 ชุด /พนง.ใหม่ 3 ชุด) | L10: ='สรุปใช้งบ 31กค'!H14 -> 457900 | M10: ='สรุปใช้งบ 31กค'!$L$14 -> 443910.8 | N10: =IFERROR(M10/L10,1) -> 0.96944922 | O10: 1204490 | P10: =O10-L10 -> 746590 | Q10: =IFERROR(O10/L10-1,1) -> 1.6304652 | R10: =IF(O10>L10,"เพิ่มขึ้น",IF(O10<L10,"ลดลง",IF(O10=L10,"--"))) -> เพิ่มขึ้น | S10: -เสื้อผ้าปรับราคาเพิ่มขึ้นมากต้องสืบราคาใหม่ -ปีก่อนๆใช้ราคามาตรฐานจาก ฝผง. ตั้งงบ ซึ่งประกาศมาตั้งแต่ปี 66 -ปี 70 จัดหาชุดพิธีการใหม่ในภาพรวมทั้งหมด -พนง.ใหม่ จัดหา 3 ชุด (ชุดพิธีการ 1 ชุด/ชุดปฏิบัติการ 2 ชุด) | T10: - | U10: 0
C11: ok | D11: 5031207000 | E11: A3-2 | F11: 3.2 ค่าเช่าอุปกรณ์ เครื่องมือ เครื่องใช้ (เช่าชุดสูท) | H11: เช่าชุดสูทปฏิบัติหน้าที่ | L11: 0 | M11: 0 | N11: =IFERROR(M11/L11,1) -> 1 | O11: ='[4]ค่าเช่าชุดสูท 70'!$E$9 -> 50000 | P11: =O11-L11 -> 50000 | Q11: =IFERROR(O11/L11-1,1) -> 1 | R11: =IF(O11>L11,"เพิ่มขึ้น",IF(O11<L11,"ลดลง",IF(O11=L11,"--"))) -> เพิ่มขึ้น | S11: ปี 70 เปลี่ยนวิธีจากเดิมตั้งงบค่าเสื้อผ้าเพื่อซื้อ/ตัด >เปลี่ยนเป็น> เช่าสูทเมื่อมีออก event ซึ่งทำให้ช่วยลดต้นทุนให้ธนาคารได้มาก | T11: - | U11: 0
C12: ok | D12: 5020306000 | E12: A4 | F12: 4. คชจ.กิจกรรมส่งเสริมค่านิยมร่วมขององค์กร (สคส.) | H12: อัตรากำลัง @1,000.- ตามที่ ฝยว. กำหนด | L12: ='สรุปใช้งบ 31กค'!H15 -> 165000 | M12: ='สรุปใช้งบ 31กค'!$L$15 -> 26800.35 | N12: =IFERROR(M12/L12,1) -> 0.16242636 | O12: ='[5]2570'!$H$13 -> 145000 | P12: =O12-L12 -> -20000 | Q12: =IFERROR(O12/L12-1,1) -> -0.12121212 | R12: =IF(O12>L12,"เพิ่มขึ้น",IF(O12<L12,"ลดลง",IF(O12=L12,"--"))) -> ลดลง | S12: -อัตรากำลังลดลงจาก 165 >> 145 คน (อัตราที่ประกาศ) | T12: - | U12: 0
C13: ok | D13: 5020402000 | E13: A5 | F13: 5. ค่าฝึกอบรมและพัฒนาพนักงาน | H13: งบฝึกอบรมและค่าใช้จ่ายในการเดินทางไปอบรม | L13: ='สรุปใช้งบ 31กค'!H16 -> 1522500 | M13: ='สรุปใช้งบ 31กค'!$L$16 -> 257470.89 | N13: =IFERROR(M13/L13,1) -> 0.1691106 | O13: ='[6]2570'!$H$14 -> 675000 | P13: =O13-L13 -> -847500 | Q13: =IFERROR(O13/L13-1,1) -> -0.55665025 | R13: =IF(O13>L13,"เพิ่มขึ้น",IF(O13<L13,"ลดลง",IF(O13=L13,"--"))) -> ลดลง | S13: ตั้งแต่ปี 69 เป็นต้นมา ฝยบ. แจ้งจำนวนงบให้ส่วนงานตั้ง | T13: - | U13: 0 | W13: ปี 71 | X13: ปี72 | Y13: ปี73
C14: ok | D14: 5031116000 | E14: A6-1 (ปี69) | F14: 6. ค่าจ้างงานรักษาความปลอดภัย | H14: ค่าจ้าง OS 5 พื้นที่ทั้วประเทศ ดังนี้ | L14: =SUM(L15:L19) -> 55490000 | M14: =SUM(M15:M19) -> 25990272 | N14: =IFERROR(M14/L14,1) -> 0.46837757 | O14: =SUM(O15:O19) -> 59880600 | P14: =O14-L14 -> 4390600 | Q14: =IFERROR(O14/L14-1,1) -> 0.079124167 | R14: =IF(O14>L14,"เพิ่มขึ้น",IF(O14<L14,"ลดลง",IF(O14=L14,"--"))) -> เพิ่มขึ้น | S14: ทุกกลุ่ม : ปี 69 ราคากลางสืบใหม่ /ปี 70 ราคาตามสัญญาซึ่งถูกกว่าราคากลาง | T14: 5 | U14: =SUM(U15:U19) -> 101283400 | W14: =SUM(W15:W19) -> 57250300 | X14: =SUM(X15:X19) -> 32895600 | Y14: =SUM(Y15:Y19) -> 11137600
H15: 1. กลุ่ม1-สนญ. | L15: =Dataผลพิปี69!U31 -> 25020000 | M15: ='[7]กลุ่ม 1'!$H$25 -> 13844752 | N15: =IFERROR(M15/L15,1) -> 0.55334742 | O15: ='[8]Template OS-2570 '!$AU$10+'[8]Template OS-2570 '!$AU$11+'[8]Template OS-2570 '!$AU$12 -> 30297600 | P15: =O15-L15 -> 5277600 | Q15: =IFERROR(O15/L15-1,1) -> 0.21093525 | R15: =IF(O15>L15,"เพิ่มขึ้น",IF(O15<L15,"ลดลง",IF(O15=L15,"--"))) -> เพิ่มขึ้น | S15: 1.กลุ่ม 1, 5 เพิ่มเนื่องจาก - กลุ่ม 1 ตั้งแต่ ธ.ค. 69 เพิ่ม 0S ห้องควบคุม 4 คน - กลุ่ม 5 ปี 70 สืบราคาเพื่อจัดซื้อใหม่ หลังบอกเลิกสัญญา สูงกว่าราคาปี 69 | T15: 1 | U15: ='[25]Template OS-2570 '!$BK$12 -> 76479500 | W15: ='[8]Template OS-2570 '!$AX$12 -> 32446300 | X15: ='[8]Template OS-2570 '!$BA$12 -> 32895600 | Y15: ='[8]Template OS-2570 '!$BD$12 -> 11137600
H16: 2. กลุ่ม2-สภน./ศชม. | L16: =Dataผลพิปี69!U32 -> 6100000 | M16: =[7]กลุ่ม2!$H$43 -> 3041731.3 | N16: =IFERROR(M16/L16,1) -> 0.49864447 | O16: ='[8]Template OS-2570 '!$AU$14 -> 5243500 | P16: =O16-L16 -> -856500 | Q16: =IFERROR(O16/L16-1,1) -> -0.14040984 | R16: =IF(O16>L16,"เพิ่มขึ้น",IF(O16<L16,"ลดลง",IF(O16=L16,"--"))) -> ลดลง | T16: 1 | U16: ='[25]Template OS-2570 '!$BK$14 -> 4372900 | W16: ='[8]Template OS-2570 '!$AX$14 -> 4373000
C17: ok | E17: A6-2 (ปี70) | H17: 3. กลุ่ม3-สภอ. | L17: =Dataผลพิปี69!U33 -> 6170000 | M17: =[9]กลุ่ม3!$H$43 -> 1942537.4 | N17: =IFERROR(M17/L17,1) -> 0.31483588 | O17: ='[8]Template OS-2570 '!$AU$18 -> 5458400 | P17: =O17-L17 -> -711600 | Q17: =IFERROR(O17/L17-1,1) -> -0.11533225 | R17: =IF(O17>L17,"เพิ่มขึ้น",IF(O17<L17,"ลดลง",IF(O17=L17,"--"))) -> ลดลง | T17: 1 | U17: ='[25]Template OS-2570 '!$BK$18 -> 4688000 | W17: ='[8]Template OS-2570 '!$AX$18 -> 4688000
H18: 4. กลุ่ม4-สภต./ศหญ. ศพง. | L18: =Dataผลพิปี69!U34 -> 6200000 | M18: =[9]กลุ่ม4!$H$43 -> 3452552.2 | N18: =IFERROR(M18/L18,1) -> 0.55686325 | O18: ='[8]Template OS-2570 '!$AU$20 -> 5949500 | P18: =O18-L18 -> -250500 | Q18: =IFERROR(O18/L18-1,1) -> -0.040403226 | R18: =IF(O18>L18,"เพิ่มขึ้น",IF(O18<L18,"ลดลง",IF(O18=L18,"--"))) -> ลดลง | S18: 2. กลุ่ม 2-5 ลดลงเนื่องจาก -กลุ่ม 2, 4 เป็นราคาราคาตามสัญญาซึ่งถูกกว่าราคากลางปี 69 -กลุ่ม 3 ราคาสัญญาหลัง stop gap สืบใหม่เริ่มสัญญาปี 70 ใช้ราคาสัญญา บ.ขอนแก่น +3% | T18: 1 | U18: ='[25]Template OS-2570 '!$BK$20 -> 4961200 | W18: ='[8]Template OS-2570 '!$AX$20 -> 4961200
H19: 5. กลุ่ม5-สอบ. ศรย. | L19: =Dataผลพิปี69!U35 -> 12000000 | M19: =[9]กลุ่ม5!$H$53 -> 3708698.3 | N19: =IFERROR(M19/L19,1) -> 0.30905819 | O19: ='[8]Template OS-2570 '!$AU$24 -> 12931600 | P19: =O19-L19 -> 931600 | Q19: =IFERROR(O19/L19-1,1) -> 0.077633333 | R19: =IF(O19>L19,"เพิ่มขึ้น",IF(O19<L19,"ลดลง",IF(O19=L19,"--"))) -> เพิ่มขึ้น | T19: 1 | U19: ='[25]Template OS-2570 '!$AP$24 -> 10781800 | W19: ='[8]Template OS-2570 '!$AX$24 -> 10781800
D20: -- | F20: 7. ค่าจ้าง/ค่าตอบแทน | H20: มี 2 ส่วน ดังนี้ | L20: =SUM(L21:L22) -> 4372900 | M20: =SUM(M21:M22) -> 2170381 | N20: =IFERROR(M20/L20,1) -> 0.49632532 | O20: =SUM(O21:O22) -> 4376900 | P20: =O20-L20 -> 4000 | Q20: =IFERROR(O20/L20-1,1) -> 0.00091472478 | R20: =IF(O20>L20,"เพิ่มขึ้น",IF(O20<L20,"ลดลง",IF(O20=L20,"--"))) -> เพิ่มขึ้น | S20: เพิ่มจากค่าจ้างแรงงานทำของ ดังนี้ | T20: - | U20: 0
B21: เอกสารแนบ สีแดง สงสัย | D21: 5031120000 | E21: A7-1 | G21: 7.1 ค่าจ้างแรงงาน/ทำของ-งานทั่วไป | H21: 1. ค่าซ่อมบัตร RFID และ ค่าตรวจสอบเครื่องอัดอากาศช่วยหายใจในการดับเพลิง | L21: ='สรุปใช้งบ 31กค'!$H$18 -> 31000 | M21: ='สรุปใช้งบ 31กค'!$L$18 -> 24931 | N21: =IFERROR(M21/L21,1) -> 0.80422581 | O21: ='[10]2570'!$C$22 -> 35000 | P21: =O21-L21 -> 4000 | Q21: =IFERROR(O21/L21-1,1) -> 0.12903226 | R21: =IF(O21>L21,"เพิ่มขึ้น",IF(O21<L21,"ลดลง",IF(O21=L21,"--"))) -> เพิ่มขึ้น | S21: ทำของ# 1. ตั้งสำรองกรณีฉุกเฉินเพิ่ม เช่น ราคาปรับตัวเพิ่มมาก มีค่าตรวจสอบใหม่ | T21: - | U21: 0
C22: 0k | D22: 5031143000 | E22: A7-2 | G22: 7.2 ค่าตอบแทนบุคคลภายนอกอื่น ๆ | H22: 2. ตร. ช่วยรักษาการณ์ ศปภ. | L22: ='สรุปใช้งบ 31กค'!$H$19 -> 4341900 | M22: ='สรุปใช้งบ 31กค'!$L$19 -> 2145450 | N22: =IFERROR(M22/L22,1) -> 0.494127 | O22: ='[11]2570'!$T$38 -> 4341900 | P22: =O22-L22 -> 0 | Q22: =IFERROR(O22/L22-1,1) -> 0 | R22: =IF(O22>L22,"เพิ่มขึ้น",IF(O22<L22,"ลดลง",IF(O22=L22,"--"))) -> -- | S22: 2. ตั้งตามอัตราที่บันทึกเลขที่ 5/66 กำหนด | T22: - | U22: 0
C23: ok | D23: 5031214000 | E23: A8 | F23: 8. ค่าซ่อมแซมและบํารุงรักษา - อุปกรณ์และระบบคอมฯ | H23: มี 3 ส่วน ดังนี้ | L23: =SUM(L24:L26) -> 2414500 | M23: =SUM(M24:M26) -> 1205595.8 | N23: =IFERROR(M23/L23,1) -> 0.49931487 | O23: =SUM(O24:O26) -> 1977164.4 | P23: =O23-L23 -> -437335.62 | Q23: =IFERROR(O23/L23-1,1) -> -0.18112886 | R23: =IF(O23>L23,"เพิ่มขึ้น",IF(O23<L23,"ลดลง",IF(O23=L23,"--"))) -> ลดลง | S23: ลดลงทั้ง 3 สัญญาดังนี้ | T23: =SUM(T24:T26) -> 2 | U23: =SUM(U24:U26) -> 2270889.4
H24: 1. ค่าซ่อมบำรุง CCTV | L24: 2263100 | M24: 1131525 | N24: =IFERROR(M24/L24,1) -> 0.49998895 | O24: ='[12]new 2570'!$E$7 -> 1844150 | P24: =O24-L24 -> -418950 | Q24: =IFERROR(O24/L24-1,1) -> -0.18512218 | R24: =IF(O24>L24,"เพิ่มขึ้น",IF(O24<L24,"ลดลง",IF(O24=L24,"--"))) -> ลดลง | S24: 1. -ปี 70 = สัญญาใหม่ เฉพาะ สนญ. -ปี 69 = ค่าซ่อมบำรุง CCTV สัญญารวมทั้ง สนญ. + สนภ. 3 แห่ง / ค่าบำรุง visitor management สนญ. + สพฐ. | T24: 1 | U24: ='[13]new 2570'!$F$7+'[13]new 2570'!$G$7 -> 2137875
H25: 2. จ้างบำรุงรักษาอุปกรณ์ Visitor Management (เครื่องอ่าน บัตรประชาชน, เครื่องอ่าน Passport, เครื่องถ่ายรูปบัตร) | L25: 106500 | M25: 53205.75 | N25: =IFERROR(M25/L25,1) -> 0.49958451 | O25: ='[12]new 2570'!$E$11 -> 133014.38 | P25: =O25-L25 -> 26514.375 | Q25: =IFERROR(O25/L25-1,1) -> 0.24896127 | R25: =IF(O25>L25,"เพิ่มขึ้น",IF(O25<L25,"ลดลง",IF(O25=L25,"--"))) -> เพิ่มขึ้น | T25: 1 | U25: ='[13]new 2570'!$F$11+'[13]new 2570'!$G$11 -> 133014.38
H26: 3. จ้างบำรุงรักษาเครื่องพิมพ์บัตร Access Card ยี่ห้อ Datacard | L26: 44900 | M26: 20865 | N26: =IFERROR(M26/L26,1) -> 0.46469933 | O26: ='[13]new 2570'!$E$15 -> 0 | P26: =O26-L26 -> -44900 | Q26: =IFERROR(O26/L26-1,1) -> -1 | R26: =IF(O26>L26,"เพิ่มขึ้น",IF(O26<L26,"ลดลง",IF(O26=L26,"--"))) -> ลดลง | S26: 2. ปี 70 ซื้อเครื่องใหม่ ให้มีเงื่อนไขซ่อมบำรุง (ระยะประกัน 3 ปี รวม MA) | T26: - | U26: 0
D27: 5031218000 | E27: A9 | F27: 9. ค่าวัสดุคอมพิวเตอร์ | H27: จัดหาบัตร Mifare /RFID /Access Card (บัตรพนักงาน) | L27: 147000 | M27: 46866 | N27: =IFERROR(M27/L27,1) -> 0.31881633 | O27: ='[14]2570'!$F$16 -> 195000 | P27: =O27-L27 -> 48000 | Q27: =IFERROR(O27/L27-1,1) -> 0.32653061 | R27: =IF(O27>L27,"เพิ่มขึ้น",IF(O27<L27,"ลดลง",IF(O27=L27,"--"))) -> เพิ่มขึ้น | S27: ราคาบัตร RFID เพิ่มขึ้นอย่างมีนัยสำคัญ (860 >> 2,500 บาท) ตั้งตามความต้องการใช้ในแต่ละปี โดยพิจารณา stock ที่มีอยู่ปัจุบันและตั้งให้พอใช้ทั้งปี 70 | T27: - | U27: 0
B28: เอกสารแนบ สีแดง สงสัย | D28: 5031219000 | E28: A10 | F28: 10. ค่าวัสดุทั่วไป | H28: 1.วัสดุในงานห้องบัตร เช่น บัตร RFID 2. วัสดุส่วนกลาง เช่น วัสดุสำนักงาน 3.วัสดุงาน รปภ. เช่น ถังดับเพลิง ผ้าคลุมรถ EV ฯลฯ | L28: ='สรุปใช้งบ 31กค'!H24 -> 305300 | M28: ='สรุปใช้งบ 31กค'!L24 -> 126239.72 | N28: =IFERROR(M28/L28,1) -> 0.41349401 | O28: ='[15]2570'!$E$8 -> 1580000 | P28: =O28-L28 -> 1274700 | Q28: =IFERROR(O28/L28-1,1) -> 4.1752375 | R28: =IF(O28>L28,"เพิ่มขึ้น",IF(O28<L28,"ลดลง",IF(O28=L28,"--"))) -> เพิ่มขึ้น | S28: ESG# มีรายการเพิ่มขึ้นอย่างมีนัยสำคัญดังนี้ -เพิ่มวัสดุเกี่ยวกับการระงับเหตุ EV ประมาณ 400,000.- -อุปกรณ์ห้องบัตร ประมาณ 370,000.- - อุปกรณ์เพื่อยกประสิทธิภาพระงับเหตุ ประมาณ 150,000.- - ถังดับเพลิง ประมาณ 800,000 บาท | T28: - | U28: 0
C29: 0k | D29: 5031138000 | E29: A11 | F29: 11. ค่าใช้จ่ายในการจัดงานและพิธีต่าง ๆ | H29: จัดงาน Financial Crime Investigation | L29: ='สรุปใช้งบ 31กค'!H26 -> 150000 | M29: ='สรุปใช้งบ 31กค'!L26 -> 0 | N29: =IFERROR(M29/L29,1) -> 0 | O29: ='[16]2570'!$D$13 -> 150000 | P29: =O29-L29 -> 0 | Q29: =IFERROR(O29/L29-1,1) -> 0 | R29: =IF(O29>L29,"เพิ่มขึ้น",IF(O29<L29,"ลดลง",IF(O29=L29,"--"))) -> -- | S29: -วางแผนจัด ก.ย.-ต.ค. (ปี 69 จัด 16-18 ก.ย.69) -จัดงานเหมือนปี69 (จัดอบรมซึ่งมีบุคคลภายนอก ไม่สามารถตั้งเป็นงบอบรมได้) | T29: - | U29: 0
C30: 0k | D30: 5031144000 | E30: A12 | F30: 12. ค่ารับรอง | H30: 1. ค่ารับรองของ ผอ. 2. ค่ารับรองของ ศปภ. 5 แห่ง | L30: ='สรุปใช้งบ 31กค'!H27 -> 80000 | M30: ='สรุปใช้งบ 31กค'!L27 -> 24068 | N30: =IFERROR(M30/L30,1) -> 0.30085 | O30: ='[17]2570'!$C$20 -> 80000 | P30: =O30-L30 -> 0 | Q30: =IFERROR(O30/L30-1,1) -> 0 | R30: =IF(O30>L30,"เพิ่มขึ้น",IF(O30<L30,"ลดลง",IF(O30=L30,"--"))) -> -- | S30: จำเป็นต้องสร้าง connection เหมือนเดิม | T30: - | U30: 0
C31: ok | D31: 5031134000 | E31: A13 | F31: 13. ค่าใช้จ่ายเดินทาง | H31: ค่าเบี้ยเลี้ยง ที่พัก และพาหนะเดินทาง มี 5 ส่วน ดังนี้ | L31: =SUM(L32:L35) -> 1597000 | M31: ='สรุปใช้งบ 31กค'!L28 -> 369502.95 | N31: =IFERROR(M31/L31,1) -> 0.23137317 | O31: =SUM(O32:O35) -> 1630000 | P31: =O31-L31 -> 33000 | Q31: =IFERROR(O31/L31-1,1) -> 0.020663745 | R31: =IF(O31>L31,"เพิ่มขึ้น",IF(O31<L31,"ลดลง",IF(O31=L31,"--"))) -> เพิ่มขึ้น | S31: ปรับกระบวนการ ศอก. ใช้คนตรวจน้อยลงเป็นสำคัญ | T31: - | U31: 0
H32: 1. ศปภ.เยี่ยมครอบครัว | L32: =Dataผลพิปี69!U63 -> 460000 | M32: n.a. | N32: =IFERROR(M32/L32,1) -> 1 | O32: ='[18]รวม คชจ.ปี 70'!$C$23 -> 480000 | P32: =O32-L32 -> 20000 | Q32: =IFERROR(O32/L32-1,1) -> 0.043478261 | R32: =IF(O32>L32,"เพิ่มขึ้น",IF(O32<L32,"ลดลง",IF(O32=L32,"--"))) -> เพิ่มขึ้น | S32: ดน.# 1.มีกลุ่มคนประจำต่างสำนักงานมากขึ้น | T32: - | U32: 0
H33: 2. ผู้บริหาร ศปก. / ศอก. เดินทางไปภูมิภาค /หชป.เวียนงาน | L33: =Dataผลพิปี69!U64 -> 587000 | M33: n.a. | N33: =IFERROR(M33/L33,1) -> 1 | O33: ='[18]รวม คชจ.ปี 70'!$C$24 -> 500000 | P33: =O33-L33 -> -87000 | Q33: =IFERROR(O33/L33-1,1) -> -0.14821124 | R33: =IF(O33>L33,"เพิ่มขึ้น",IF(O33<L33,"ลดลง",IF(O33=L33,"--"))) -> ลดลง | S33: ดน.# 2.ศอก./ศปภ. ใช้คนตรวจน้อยลง / ทริป ผอ. ลดลง | T33: - | U33: 0
H34: 3. ศปภ. โยกย้าย | L34: =Dataผลพิปี69!U65 -> 400000 | M34: n.a. | N34: =IFERROR(M34/L34,1) -> 1 | O34: ='[18]รวม คชจ.ปี 70'!$C$24 -> 500000 | P34: =O34-L34 -> 100000 | Q34: =IFERROR(O34/L34-1,1) -> 0.25 | R34: =IF(O34>L34,"เพิ่มขึ้น",IF(O34<L34,"ลดลง",IF(O34=L34,"--"))) -> เพิ่มขึ้น | S34: ดน.# 3.โยกย้ายมากขึ้น เมื่อหลักเกณฑ์ท้องถิ่นออกปีแรก | T34: - | U34: 0
H35: 4. งานสืบสวนและประมวลข่าว | L35: =Dataผลพิปี69!U66 -> 150000 | M35: n.a. | N35: =IFERROR(M35/L35,1) -> 1 | O35: ='[18]รวม คชจ.ปี 70'!$C$26 -> 150000 | P35: =O35-L35 -> 0 | Q35: =IFERROR(O35/L35-1,1) -> 0 | R35: =IF(O35>L35,"เพิ่มขึ้น",IF(O35<L35,"ลดลง",IF(O35=L35,"--"))) -> -- | S35: ดน.# 4. ตั้งเท่าปีก่อน /เพียงพอใช้ | T35: - | U35: 0
C36: ok | D36: 5031107000 | E36: A14 | F36: 14. ค่าธรรมเนียมอื่น ๆ | H36: 1. ค่าความถี่และค่าต่ออายุวิทยุสื่อสาร 2. ใบอนุญาตยุทธภัณฑ์ 3. ค่าตรวจรังสี พนง.รปภ. 7 เครื่อง และ 14 คน 4. ค่าจัดสรรคลื่นความถี่วิทยุ 5. ใบอนุญาตครอบครองเครื่องกำเนิดรังสี | L36: ='สรุปใช้งบ 31กค'!H29 -> 27000 | M36: ='สรุปใช้งบ 31กค'!L29 -> 1177 | N36: =IFERROR(M36/L36,1) -> 0.043592593 | O36: ='[19]2570'!$D$28 -> 40000 | P36: =O36-L36 -> 13000 | Q36: =IFERROR(O36/L36-1,1) -> 0.48148148 | R36: =IF(O36>L36,"เพิ่มขึ้น",IF(O36<L36,"ลดลง",IF(O36=L36,"--"))) -> เพิ่มขึ้น | S36: -ค่าธรรมเนียมใหม่ ได้แก่ ค่าบริการ Internet SIM รายปี สำหรับ Body Camara -สำรองฉุกเฉิน | T36: - | U36: 0 | W36: ปี 71
B37: มีโปรใช้ร่วมกัน | C37: เช็คโปร? | D37: 5031118000 | E37: A15-1 | F37: 15. ค่าสิทธิ์การใช้โปรแกรมส่วนงาน | H37: ใช้โปรแกรม Canva Pro 4 license | L37: ='สรุปใช้งบ 31กค'!H32 -> 6300 | M37: ='สรุปใช้งบ 31กค'!L32 -> 5550 | N37: =IFERROR(M37/L37,1) -> 0.88095238 | O37: ='[20]ค่าสิทธิการใช้โปรแกรม ปี 70'!$H$202 -> 8800 | P37: =O37-L37 -> 2500 | Q37: =IFERROR(O37/L37-1,1) -> 0.3968254 | R37: =IF(O37>L37,"เพิ่มขึ้น",IF(O37<L37,"ลดลง",IF(O37=L37,"--"))) -> เพิ่มขึ้น | S37: DATA# เพิ่ม 1 licence รวมเป็น 4 licence (ศอก. 2, ศสป. 1, ศปภ. 1) | T37: 4 | U37: ='[20]ค่าสิทธิการใช้โปรแกรม ปี 70'!$I$202 -> 8800 | W37: =U37 -> 8800
C38: ok | D38: 5031133000 | E38: A15-2 | F38: 16. ค่าสิทธิ์การใช้โปรแกรมส่วนกลาง | H38: ใช้โปรแกรม Adobe 1 license | L38: ='สรุปใช้งบ 31กค'!H33 -> 23000 | M38: =L38 -> 23000 | N38: =IFERROR(M38/L38,1) -> 1 | O38: ='[21]ค่าสิทธิการใช้โปรแกรม ปี 70'!$H$202 -> 48000 | P38: =O38-L38 -> 25000 | Q38: =IFERROR(O38/L38-1,1) -> 1.0869565 | R38: =IF(O38>L38,"เพิ่มขึ้น",IF(O38<L38,"ลดลง",IF(O38=L38,"--"))) -> เพิ่มขึ้น | S38: DATA# เพิ่ม 1 licence รวมเป็น 2 licence (พนง. 1,OS 1) + ราคาปรับตัวเพิ่ม | T38: 1 | U38: ='[21]ค่าสิทธิการใช้โปรแกรม ปี 70'!$I$202 -> 0
C39: ok | D39: 5031131000 | E39: A16 | F39: 17. ค่าใช้จ่ายในการสืบสวนเกี่ยวกับงาน รปภ. | H39: ใช้สืบสวนของ ทสส.1-2 | L39: ='สรุปใช้งบ 31กค'!H30 -> 220000 | M39: ='สรุปใช้งบ 31กค'!L30 -> 60000 | N39: =IFERROR(M39/L39,1) -> 0.27272727 | O39: ='[22]2570'!$E$7 -> 220000 | P39: =O39-L39 -> 0 | Q39: =IFERROR(O39/L39-1,1) -> 0 | R39: =IF(O39>L39,"เพิ่มขึ้น",IF(O39<L39,"ลดลง",IF(O39=L39,"--"))) -> -- | S39: ตั้งเท่าปีก่อน /เพียงพอใช้ | T39: - | U39: 0
C40: หน่วยงานที่ขอตั้ง | D40: 2. หมวดสินทรัพย์ถาวร | H40: จำนวนปี 69 | I40: ราคา @ ปี 69 | J40: จำนวนปี 70 | K40: ราคา @ ปี 70 | L40: =SUM(L41:L80) -> 29633600 | M40: =SUM(M41:M80) -> 25341985 | N40: =IFERROR(M40/L40,1) -> 0.8551774 | O40: =SUM(O41:O80) -> 35641500 | P40: =O40-L40 -> 6007900 | Q40: =IFERROR(O40/L40-1,1) -> 0.20273946 | R40: =IF(O40>L40,"เพิ่มขึ้น",IF(O40<L40,"ลดลง",IF(O40=L40,"--"))) -> เพิ่มขึ้น | U40: =SUM(U41:U80) -> 0
B41: รอแบบขอ / ฝจอ ไม่บวก 10% | C41: ฝจอ ไม่บวกราคา | D41: AUC | E41: B1 | F41: ระบบห้องควบคุม ฝรภ. อาคาร 1 และ 2 (Wall monitor ห้องควบคุม อาคาร 1, 2 และซื้อเครื่อง HDR จำนวน 9 เครื่อง และ work station จำนวน 1 เครื่องห้องควบคุมอาคาร 2) | H41: -- | I41: 0 | J41: 1 | K41: =ROUNDUP(1630894,-4) -> 1640000 | N41: =IFERROR(M41/L41,1) -> 1 | O41: =K41*J41 -> 1640000 | P41: =O41-L41 -> 1640000 | Q41: =IFERROR(O41/L41-1,1) -> 1 | R41: =IF(O41>L41,"เพิ่มขึ้น",IF(O41<L41,"ลดลง",IF(O41=L41,"--"))) -> เพิ่มขึ้น | S41: เป็นการปรับปรุงเพื่อให้รองรับการปฏิบัติงาน OS และการกำกับควบคุม OS ซึ่งผ่านการหารือ ฝจอ. ฝทส. ฝสภ. แล้ว
...

Sheet คำขอปึ70คชจ
B1: =(18990)*105% -> 19939.5 | C1: =80000/6 -> 13333.333 | D1: สรุปรายละเอียดคำขอตั้งงบประมาณของฝ่ายรักษาความปลอดภัย ประจำปี 2570 - สิ้นสุด
D3: รหัสงบฯ | E3: File ประกอบ | F3: ชื่องบประมาณ/ชื่อบัญชี | H3: คำนิยาม | L3: งบปี 2569 | O3: คำขอปี 2570 ( เพิ่มขึ้น / ลดลง ) | T3: คำขอปี 2570 - สิ้นสุด
L4: งบที่ได้ปี 69 +จัดสรรระหว่างปี | M4: ใช้ไป ณ 31 ก.ค. 69 | N4: %ใช้ไป ปี 2569 | O4: งบปี 2570 | P4: เทียบกับ ปี 2569 | Q4: % เทียบกับ ปี 2569 | R4: เปลี่ยนแปลง | S4: เหตุผล | T4: หน่วย | U4: จำนวนเงิน
D5: 1. หมวดค่าใช้จ่าย | L5: =SUM(L6,L9:L14,L20,L23,L27:L31,L36:L39) -> 83953200 | M5: =SUM(M6,M9:M14,M20,M23,M27:M31,M36:M39) -> 38792696 | N5: =IFERROR(M5/L5-1,1) -> -0.53792475 | O5: =SUM(O6,O9:O14,O20,O23,O27:O31,O36:O39) -> 83608454 | P5: =O5-L5 -> -344745.62 | Q5: =IFERROR(O5/L5-1,1) -> -0.0041064024 | R5: =IF(O5>L5,"เพิ่มขึ้น",IF(O5<L5,"ลดลง",IF(O5=L5,"--"))) -> ลดลง | S5: อัตรา ฝรภ. กำลังลดลง /จัดซื้อ OS ได้ราคาถูกลง /MA สนภ.ตั้งงบเอง | T5: =SUM(T14,T23,T37,T38) -> 12 | U5: =SUM(U6,U9:U14,U20,U23,U27:U31,U36:U39) -> 1.0356309e+08
D6: -- | F6: 1. ค่าตอบแทนการทำงานนอกเวลา | H6: มี 2 ส่วน ดังนี้ | L6: =SUM(L7:L8) -> 5950000 | M6: =SUM(M7:M8) -> 3752559.2 | N6: =IFERROR(M6/L6-1,1) -> -0.36931778 | O6: =SUM(O8:O8) -> 6200000 | P6: =O6-L6 -> 250000 | Q6: =IFERROR(O6/L6-1,1) -> 0.042016807 | R6: =IF(O6>L6,"เพิ่มขึ้น",IF(O6<L6,"ลดลง",IF(O6=L6,"--"))) -> เพิ่มขึ้น | S6: เพิ่มทั้งหมวด OT + ศปภ. เข้าเวร ดังนี้ | T6: - | U6: 0
C7: ok | D7: ='สรุปใช้งบ 31กค'!B11 -> 5020102000 | E7: A1-1 | G7: 1.1 ค่าล่วงเวลาและค่าตอบแทนการทำงานเกินเวลา | H7: 1.-ฝรภ.ปฏิบัติงานแทน OS หยุดงาน+เกิดเหตุไม่ปกติ -ศสป. ศอก. สนับสนุนงาน ศปภ. วันหยุด+นอกเวลางาน -ฝรภ. ปฏิบัติงานเร่งด่วน วันหยุด+นอกเวลางาน | L7: ='สรุปใช้งบ 31กค'!H11 -> 310000 | M7: ='สรุปใช้งบ 31กค'!L11 -> 263759.21 | N7: =IFERROR(M7/L7-1,1) -> -0.14916384 | O7: =[1]คำขอ2570!$F$8 -> 890000 | P7: =O7-L7 -> 580000 | Q7: =IFERROR(O7/L7-1,1) -> 1.8709677 | R7: =IF(O7>L7,"เพิ่มขึ้น",IF(O7<L7,"ลดลง",IF(O7=L7,"--"))) -> เพิ่มขึ้น | S7: 1.-ศปภ. ปรับการปฏิบัติงานให้สอดคล้อง กม.ใหม่ (หารือ ฝกม.แล้ว) -ศอก. ศสป. ตั้งเพิ่มจากเหตุปฏิบัติงานแทน OS เหตุบอกเลิกสัญญาปี 69 และสำรองงานเร่งด่วนนอกเวลา | T7: - | U7: 0
B8: มีปรับตาราง | C8: ok | D8: ='สรุปใช้งบ 31กค'!B12 -> 5020104000 | E8: A1-2 | G8: 1.2 เงินช่วยเหลือพิเศษ | H8: 2. ค่าเข้าเวร นอกเวลาปกติ/ วันหยุด | L8: ='สรุปใช้งบ 31กค'!H12 -> 5640000 | M8: ='สรุปใช้งบ 31กค'!L12 -> 3488800 | N8: =IFERROR(M8/L8-1,1) -> -0.38141844 | O8: ='[2]2570new'!$D$21 -> 6200000 | P8: =O8-L8 -> 560000 | Q8: =IFERROR(O8/L8-1,1) -> 0.09929078 | R8: =IF(O8>L8,"เพิ่มขึ้น",IF(O8<L8,"ลดลง",IF(O8=L8,"--"))) -> เพิ่มขึ้น | S8: 2.-อัตรากำลังลดลงจากปีก่อน 108 >> 103 คน -90% เป็น พนง.เก่าจึงต้องปรับฐานเงินเดือนเฉลี่ยเพิ่มอีก 2.5% เพื่อให้พอต่อการใช้จ่ายปี 70 | T8: - | U8: 0
B9: เอกสารแนบ สีแดง สงสัย | D9: ='สรุปใช้งบ 31กค'!B13 -> 5020305000 | E9: A2 | F9: 2. เงินช่วยเหลืออื่น ๆ (ปฏิบัติงานต่าง สนง.) | H9: 1. ค่าจัดซื้อของเหมาจ่าย (ให้ครั้งเดียว และเมื่อย้าย) 2. บ้านพัก/ค่าเช่าบ้าน @ 8,000/เดือน 3. เงินช่วยเหลือพิเศษ @ 5,500/เดือน | L9: ='สรุปใช้งบ 31กค'!H13 -> 6650000 | M9: ='สรุปใช้งบ 31กค'!$L$13 -> 2100323.9 | N9: =IFERROR(M9/L9-1,1) -> -0.68416183 | O9: ='[3]1. ต่างสำนักงาน Rate ปี 70'!$F$20 -> 4380000 | P9: =O9-L9 -> -2270000 | Q9: =IFERROR(O9/L9-1,1) -> -0.34135338 | R9: =IF(O9>L9,"เพิ่มขึ้น",IF(O9<L9,"ลดลง",IF(O9=L9,"--"))) -> ลดลง | S9: -อัตรากำลังลดลงจาก 108 >> 103 คน -ปี 70 ศปภ.ครบวงรอบย้ายลดลง | T9: - | U9: 0
B10: รอราคา | D10: ='สรุปใช้งบ 31กค'!B14 -> 5020304000 | E10: A3-1 | F10: 3.1 ค่าเสื้อผ้าและเครื่องแบบ | H10: แจก ชุดปฏิบัติการ / ชุดพิธีการ (พนง.เก่า 2 ชุด /พนง.ใหม่ 3 ชุด) | L10: ='สรุปใช้งบ 31กค'!H14 -> 457900 | M10: ='สรุปใช้งบ 31กค'!$L$14 -> 443910.8 | N10: =IFERROR(M10/L10-1,1) -> -0.030550775 | O10: 1204490 | P10: =O10-L10 -> 746590 | Q10: =IFERROR(O10/L10-1,1) -> 1.6304652 | R10: =IF(O10>L10,"เพิ่มขึ้น",IF(O10<L10,"ลดลง",IF(O10=L10,"--"))) -> เพิ่มขึ้น | S10: -เสื้อผ้าปรับราคาเพิ่มขึ้นมากต้องสืบราคาใหม่ -ปีก่อนๆใช้ราคามาตรฐานจาก ฝผง. ตั้งงบ ซึ่งประกาศมาตั้งแต่ปี 66 -ปี 70 จัดหาชุดพิธีการใหม่ในภาพรวมทั้งหมด -พนง.ใหม่ จัดหา 3 ชุด (ชุดพิธีการ 1 ชุด/ชุดปฏิบัติการ 2 ชุด) | T10: - | U10: 0 | X10: ตรวจเอกสารแนบ
C11: ok | D11: ='สรุปใช้งบ 31กค'!B15 -> 5020306000 | E11: A3-2 | F11: 3.2 ค่าเช่าอุปกรณ์ เครื่องมือ เครื่องใช้ (เช่าชุดสูท) | H11: เช่าชุดสูทปฏิบัติหน้าที่ | L11: 0 | M11: 0 | N11: =IFERROR(M11/L11-1,1) -> 1 | O11: ='[4]ค่าเช่าชุดสูท 70'!$E$9 -> 50000 | P11: =O11-L11 -> 50000 | Q11: =IFERROR(O11/L11-1,1) -> 1 | R11: =IF(O11>L11,"เพิ่มขึ้น",IF(O11<L11,"ลดลง",IF(O11=L11,"--"))) -> เพิ่มขึ้น | S11: ปี 70 เปลี่ยนวิธีจากเดิมตั้งงบค่าเสื้อผ้าเพื่อซื้อ/ตัด >เปลี่ยนเป็น> เช่าสูทเมื่อมีออก event ซึ่งทำให้ช่วยลดต้นทุนให้ธนาคารได้มาก | T11: - | U11: 0
C12: ok | D12: ='สรุปใช้งบ 31กค'!B15 -> 5020306000 | E12: A4 | F12: 4. คชจ.กิจกรรมส่งเสริมค่านิยมร่วมขององค์กร (สคส.) | H12: อัตรากำลัง @1,000.- ตามที่ ฝยว. กำหนด | L12: ='สรุปใช้งบ 31กค'!H15 -> 165000 | M12: ='สรุปใช้งบ 31กค'!$L$15 -> 26800.35 | N12: =IFERROR(M12/L12-1,1) -> -0.83757364 | O12: ='[5]2570'!$H$13 -> 145000 | P12: =O12-L12 -> -20000 | Q12: =IFERROR(O12/L12-1,1) -> -0.12121212 | R12: =IF(O12>L12,"เพิ่มขึ้น",IF(O12<L12,"ลดลง",IF(O12=L12,"--"))) -> ลดลง | S12: -อัตรากำลังลดลงจาก 165 >> 145 คน (อัตราที่ประกาศ) | T12: - | U12: 0
C13: ok | D13: ='สรุปใช้งบ 31กค'!B16 -> 5020402000 | E13: A5 | F13: 5. ค่าฝึกอบรมและพัฒนาพนักงาน | H13: งบฝึกอบรมและค่าใช้จ่ายในการเดินทางไปอบรม | L13: ='สรุปใช้งบ 31กค'!H16 -> 1522500 | M13: ='สรุปใช้งบ 31กค'!$L$16 -> 257470.89 | N13: =IFERROR(M13/L13-1,1) -> -0.8308894 | O13: ='[26]2570'!$H$15 -> 1522500 | P13: =O13-L13 -> 0 | Q13: =IFERROR(O13/L13-1,1) -> 0 | R13: =IF(O13>L13,"เพิ่มขึ้น",IF(O13<L13,"ลดลง",IF(O13=L13,"--"))) -> -- | S13: -ปี 70 = อัตราที่ประกาศทางการ 145 คน -ปี 69 = อัตราที่ยังไม่ประกาศทางการ 145 คน | T13: - | U13: 0
C14: ok | D14: ='สรุปใช้งบ 31กค'!B17 -> 5031116000 | E14: A6-1 (ปี69) | F14: 6. ค่าจ้างงานรักษาความปลอดภัย | H14: ค่าจ้าง OS 5 พื้นที่ทั้วประเทศ ดังนี้ | L14: =SUM(L15:L19) -> 55490000 | M14: =SUM(M15:M19) -> 25990272 | N14: =IFERROR(M14/L14-1,1) -> -0.53162243 | O14: =SUM(O15:O19) -> 59880600 | P14: =O14-L14 -> 4390600 | Q14: =IFERROR(O14/L14-1,1) -> 0.079124167 | R14: =IF(O14>L14,"เพิ่มขึ้น",IF(O14<L14,"ลดลง",IF(O14=L14,"--"))) -> เพิ่มขึ้น | S14: ทุกกลุ่ม : ปี 69 ราคากลางสืบใหม่ /ปี 70 ราคาตามสัญญาซึ่งถูกกว่าราคากลาง | T14: 5 | U14: =SUM(U15:U19) -> 101283400
H15: 1. กลุ่ม1-สนญ. | L15: =Dataผลพิปี69!U31 -> 25020000 | M15: ='[7]กลุ่ม 1'!$H$25 -> 13844752 | N15: =IFERROR(M15/L15-1,1) -> -0.44665258 | O15: ='[25]Template OS-2570 '!$AU$10+'[25]Template OS-2570 '!$AU$11+'[25]Template OS-2570 '!$AU$12 -> 30297600 | P15: =O15-L15 -> 5277600 | Q15: =IFERROR(O15/L15-1,1) -> 0.21093525 | R15: =IF(O15>L15,"เพิ่มขึ้น",IF(O15<L15,"ลดลง",IF(O15=L15,"--"))) -> เพิ่มขึ้น | S15: 1.กลุ่ม 1, 5 เพิ่มเนื่องจาก - กลุ่ม 1 ตั้งแต่ ธ.ค. 69 เพิ่ม 0S ห้องควบคุม 4 คน - กลุ่ม 5 ปี 70 สืบราคาเพื่อจัดซื้อใหม่ หลังบอกเลิกสัญญา สูงกว่าราคาปี 69 | T15: 1 | U15: ='[25]Template OS-2570 '!$BK$12 -> 76479500
H16: 2. กลุ่ม2-สภน./ศชม. | L16: =Dataผลพิปี69!U32 -> 6100000 | M16: =[7]กลุ่ม2!$H$43 -> 3041731.3 | N16: =IFERROR(M16/L16-1,1) -> -0.50135553 | O16: ='[25]Template OS-2570 '!$AU$14 -> 5243500 | P16: =O16-L16 -> -856500 | Q16: =IFERROR(O16/L16-1,1) -> -0.14040984 | R16: =IF(O16>L16,"เพิ่มขึ้น",IF(O16<L16,"ลดลง",IF(O16=L16,"--"))) -> ลดลง | T16: 1 | U16: ='[25]Template OS-2570 '!$BK$14 -> 4372900
C17: ok | E17: A6-2 (ปี70) | H17: 3. กลุ่ม3-สภอ. | L17: =Dataผลพิปี69!U33 -> 6170000 | M17: =[9]กลุ่ม3!$H$43 -> 1942537.4 | N17: =IFERROR(M17/L17-1,1) -> -0.68516412 | O17: ='[25]Template OS-2570 '!$AU$18 -> 5458400 | P17: =O17-L17 -> -711600 | Q17: =IFERROR(O17/L17-1,1) -> -0.11533225 | R17: =IF(O17>L17,"เพิ่มขึ้น",IF(O17<L17,"ลดลง",IF(O17=L17,"--"))) -> ลดลง | T17: 1 | U17: ='[25]Template OS-2570 '!$BK$18 -> 4688000
H18: 4. กลุ่ม4-สภต./ศหญ. ศสร. ศพง. | L18: =Dataผลพิปี69!U34 -> 6200000 | M18: =[9]กลุ่ม4!$H$43 -> 3452552.2 | N18: =IFERROR(M18/L18-1,1) -> -0.44313675 | O18: ='[25]Template OS-2570 '!$AU$20 -> 5949500 | P18: =O18-L18 -> -250500 | Q18: =IFERROR(O18/L18-1,1) -> -0.040403226 | R18: =IF(O18>L18,"เพิ่มขึ้น",IF(O18<L18,"ลดลง",IF(O18=L18,"--"))) -> ลดลง | S18: 2. กลุ่ม 2-5 ลดลงเนื่องจาก -กลุ่ม 2, 4 เป็นราคาราคาตามสัญญาซึ่งถูกกว่าราคากลางปี 69 -กลุ่ม 3 ราคาสัญญาหลัง stop gap สืบใหม่ปี 70 ใช้ราคาสัญญา บ.ขอนแก่น +3% | T18: 1 | U18: ='[25]Template OS-2570 '!$BK$20 -> 4961200
H19: 5. กลุ่ม5-สอบ. ศรย. | L19: =Dataผลพิปี69!U35 -> 12000000 | M19: =[9]กลุ่ม5!$H$53 -> 3708698.3 | N19: =IFERROR(M19/L19-1,1) -> -0.69094181 | O19: ='[25]Template OS-2570 '!$AU$24 -> 12931600 | P19: =O19-L19 -> 931600 | Q19: =IFERROR(O19/L19-1,1) -> 0.077633333 | R19: =IF(O19>L19,"เพิ่มขึ้น",IF(O19<L19,"ลดลง",IF(O19=L19,"--"))) -> เพิ่มขึ้น | T19: 1 | U19: ='[25]Template OS-2570 '!$AP$24 -> 10781800
D20: -- | F20: 7. ค่าจ้าง/ค่าตอบแทน | H20: มี 2 ส่วน ดังนี้ | L20: =SUM(L21:L22) -> 4372900 | M20: =SUM(M21:M22) -> 2170381 | N20: =IFERROR(M20/L20-1,1) -> -0.50367468 | O20: =SUM(O21:O22) -> 4376900 | P20: =O20-L20 -> 4000 | Q20: =IFERROR(O20/L20-1,1) -> 0.00091472478 | R20: =IF(O20>L20,"เพิ่มขึ้น",IF(O20<L20,"ลดลง",IF(O20=L20,"--"))) -> เพิ่มขึ้น | S20: เพิ่มจากค่าจ้างแรงงานทำของ ดังนี้ | T20: - | U20: 0
B21: เอกสารแนบ สีแดง สงสัย | D21: ='สรุปใช้งบ 31กค'!B18 -> 5031120000 | E21: A7-1 | G21: 7.1 ค่าจ้างแรงงาน/ทำของ-งานทั่วไป | H21: 1. ค่าซ่อมบัตร RFID และ ค่าตรวจสอบเครื่องอัดอากาศช่วยหายใจในการดับเพลิง | L21: ='สรุปใช้งบ 31กค'!$H$18 -> 31000 | M21: ='สรุปใช้งบ 31กค'!$L$18 -> 24931 | N21: =IFERROR(M21/L21-1,1) -> -0.19577419 | O21: ='[10]2570'!$C$22 -> 35000 | P21: =O21-L21 -> 4000 | Q21: =IFERROR(O21/L21-1,1) -> 0.12903226 | R21: =IF(O21>L21,"เพิ่มขึ้น",IF(O21<L21,"ลดลง",IF(O21=L21,"--"))) -> เพิ่มขึ้น | S21: 1. ตั้งสำรองกรณีฉุกเฉินเพิ่ม เช่น ราคาปรับตัวเพิ่มมาก มีค่าตรวจสอบใหม่ | T21: - | U21: 0
C22: 0k | D22: ='สรุปใช้งบ 31กค'!B19 -> 5031143000 | E22: A7-2 | G22: 7.2 ค่าตอบแทนบุคคลภายนอกอื่น ๆ | H22: 2. ตร. ช่วยรักษาการณ์ ศปภ. | L22: ='สรุปใช้งบ 31กค'!$H$19 -> 4341900 | M22: ='สรุปใช้งบ 31กค'!$L$19 -> 2145450 | N22: =IFERROR(M22/L22-1,1) -> -0.505873 | O22: ='[11]2570'!$T$38 -> 4341900 | P22: =O22-L22 -> 0 | Q22: =IFERROR(O22/L22-1,1) -> 0 | R22: =IF(O22>L22,"เพิ่มขึ้น",IF(O22<L22,"ลดลง",IF(O22=L22,"--"))) -> -- | S22: 2. ตั้งตามอัตราที่บันทึกเลขที่ 5/66 กำหนด | T22: - | U22: 0
C23: ok | D23: 5031214000 | E23: A8 | F23: 8. ค่าซ่อมแซมและบํารุงรักษา - อุปกรณ์และระบบคอมฯ | H23: มี 3 ส่วน ดังนี้ | L23: =SUM(L24:L26) -> 6789300 | M23: =SUM(M24:M26) -> 3394575 | N23: =IFERROR(M23/L23-1,1) -> -0.50001105 | O23: =SUM(O24:O26) -> 1977164.4 | P23: =O23-L23 -> -4812135.6 | Q23: =IFERROR(O23/L23-1,1) -> -0.70878229 | R23: =IF(O23>L23,"เพิ่มขึ้น",IF(O23<L23,"ลดลง",IF(O23=L23,"--"))) -> ลดลง | S23: ลดลงทั้ง 3 สัญญาดังนี้ | T23: =SUM(T24:T26) -> 2 | U23: =SUM(U24:U26) -> 2270889.4
H24: 1. ค่าซ่อมบำรุง CCTV | L24: ='สรุปใช้งบ 31กค'!$I$21 -> 2263100 | M24: ='สรุปใช้งบ 31กค'!$L$21 -> 1131525 | N24: =IFERROR(M24/L24-1,1) -> -0.50001105 | O24: ='[12]new 2570'!$E$7 -> 1844150 | P24: =O24-L24 -> -418950 | Q24: =IFERROR(O24/L24-1,1) -> -0.18512218 | R24: =IF(O24>L24,"เพิ่มขึ้น",IF(O24<L24,"ลดลง",IF(O24=L24,"--"))) -> ลดลง | S24: 1. -ปี 70 = สัญญาใหม่ เฉพาะ สนญ. -ปี 69 = ค่าซ่อมบำรุง CCTV สัญญารวมทั้ง สนญ. + สนภ. 3 แห่ง / ค่าบำรุง visitor management สนญ. + สพฐ. | T24: 1 | U24: ='[13]new 2570'!$F$7+'[13]new 2570'!$G$7 -> 2137875
H25: 2. จ้างบำรุงรักษาอุปกรณ์ Visitor Management (เครื่องอ่านบัตรประชาชน, เครื่องอ่าน Passport, เครื่องถ่ายรูปบัตร) | L25: ='สรุปใช้งบ 31กค'!$I$21 -> 2263100 | M25: ='สรุปใช้งบ 31กค'!$L$21 -> 1131525 | N25: =IFERROR(M25/L25-1,1) -> -0.50001105 | O25: ='[12]new 2570'!$E$11 -> 133014.38 | P25: =O25-L25 -> -2130085.6 | Q25: =IFERROR(O25/L25-1,1) -> -0.9412247 | R25: =IF(O25>L25,"เพิ่มขึ้น",IF(O25<L25,"ลดลง",IF(O25=L25,"--"))) -> ลดลง | T25: 1 | U25: ='[13]new 2570'!$F$11+'[13]new 2570'!$G$11 -> 133014.38
H26: 3. จ้างบำรุงรักษาเครื่องพิมพ์บัตร Access Card ยี่ห้อ Datacard | L26: ='สรุปใช้งบ 31กค'!$I$21 -> 2263100 | M26: ='สรุปใช้งบ 31กค'!$L$21 -> 1131525 | N26: =IFERROR(M26/L26-1,1) -> -0.50001105 | O26: ='[13]new 2570'!$E$15 -> 0 | P26: =O26-L26 -> -2263100 | Q26: =IFERROR(O26/L26-1,1) -> -1 | R26: =IF(O26>L26,"เพิ่มขึ้น",IF(O26<L26,"ลดลง",IF(O26=L26,"--"))) -> ลดลง | S26: 2. ปี 70 ซื้อเครื่องใหม่ ให้มีเงื่อนไขซ่อมบำรุง (ระยะประกัน 3 ปี รวม MA) | T26: - | U26: 0
D27: ='สรุปใช้งบ 31กค'!B31 -> 5031218000 | E27: A9 | F27: 9. ค่าวัสดุคอมพิวเตอร์ | H27: จัดหาบัตร Mifare /RFID /Access Card (บัตรพนักงาน) | L27: ='สรุปใช้งบ 31กค'!H31 -> 147000 | M27: ='สรุปใช้งบ 31กค'!L31 -> 46866 | N27: =IFERROR(M27/L27-1,1) -> -0.68118367 | O27: ='[14]2570'!$F$16 -> 195000 | P27: =O27-L27 -> 48000 | Q27: =IFERROR(O27/L27-1,1) -> 0.32653061 | R27: =IF(O27>L27,"เพิ่มขึ้น",IF(O27<L27,"ลดลง",IF(O27=L27,"--"))) -> เพิ่มขึ้น | S27: ราคาบัตร RFID เพิ่มขึ้นอย่างมีนัยสำคัญ (860 >> 2,500 บาท) ตั้งตามความต้องการใช้ในแต่ละปี โดยพิจารณา stock ที่มีอยู่ปัจุบันและตั้งให้พอใช้ทั้งปี 70 | T27: - | U27: 0
B28: เอกสารแนบ สีแดง สงสัย | D28: 5031219000 | E28: A10 | F28: 10. ค่าวัสดุทั่วไป | H28: 1.วัสดุในงานห้องบัตร เช่น บัตร RFID 2. วัสดุส่วนกลาง เช่น วัสดุสำนักงาน 3.วัสดุงาน รปภ. เช่น ถังดับเพลิง ผ้าคลุมรถ EV ฯลฯ | L28: ='สรุปใช้งบ 31กค'!H24 -> 305300 | M28: ='สรุปใช้งบ 31กค'!L24 -> 126239.72 | N28: =IFERROR(M28/L28-1,1) -> -0.58650599 | O28: ='[15]2570'!$E$8 -> 1580000 | P28: =O28-L28 -> 1274700 | Q28: =IFERROR(O28/L28-1,1) -> 4.1752375 | R28: =IF(O28>L28,"เพิ่มขึ้น",IF(O28<L28,"ลดลง",IF(O28=L28,"--"))) -> เพิ่มขึ้น | S28: มีรายการเพิ่มขึ้นอย่างมีนัยสำคัญดังนี้ -เพิ่มวัสดุเกี่ยวกับการระงับเหตุ EV ประมาณ 400,000.- -อุปกรณ์ห้องบัตร ประมาณ 370,000.- - อุปกรณ์เพื่อยกประสิทธิภาพระงับเหตุ ประมาณ 150,000.- | T28: - | U28: 0
C29: 0k | D29: ='สรุปใช้งบ 31กค'!B26 -> 5031138000 | E29: A11 | F29: 11. ค่าใช้จ่ายในการจัดงานและพิธีต่าง ๆ | H29: จัดงาน Financial Crime Investigation | L29: ='สรุปใช้งบ 31กค'!H26 -> 150000 | M29: ='สรุปใช้งบ 31กค'!L26 -> 0 | N29: =IFERROR(M29/L29-1,1) -> -1 | O29: ='[16]2570'!$D$13 -> 150000 | P29: =O29-L29 -> 0 | Q29: =IFERROR(O29/L29-1,1) -> 0 | R29: =IF(O29>L29,"เพิ่มขึ้น",IF(O29<L29,"ลดลง",IF(O29=L29,"--"))) -> -- | S29: -วางแผนจัด ก.ย.-ต.ค. 69 (ปี 69 จัด 16-18 ก.ย.69) -จัดงานเหมือนปี69 (จัดอบรมซึ่งมีบุคคลภายนอก ไม่สามารถตั้งเป็นงบอบรมได้) | T29: - | U29: 0
C30: 0k | D30: ='สรุปใช้งบ 31กค'!B27 -> 5031144000 | E30: A12 | F30: 12. ค่ารับรอง | H30: 1. ค่ารับรองของ ผอ. 2. ค่ารับรองของ ศปภ. 5 แห่ง | L30: ='สรุปใช้งบ 31กค'!H27 -> 80000 | M30: ='สรุปใช้งบ 31กค'!L27 -> 24068 | N30: =IFERROR(M30/L30-1,1) -> -0.69915 | O30: ='[17]2570'!$C$20 -> 80000 | P30: =O30-L30 -> 0 | Q30: =IFERROR(O30/L30-1,1) -> 0 | R30: =IF(O30>L30,"เพิ่มขึ้น",IF(O30<L30,"ลดลง",IF(O30=L30,"--"))) -> -- | S30: จำเป็นต้องสร้าง connection เหมือนเดิม | T30: - | U30: 0
C31: ok | D31: ='สรุปใช้งบ 31กค'!B28 -> 5031134000 | E31: A13 | F31: 13. ค่าใช้จ่ายเดินทาง | H31: ค่าเบี้ยเลี้ยง ที่พัก และพาหนะเดินทาง มี 5 ส่วน ดังนี้ | L31: =SUM(L32:L35) -> 1597000 | M31: ='สรุปใช้งบ 31กค'!L28 -> 369502.95 | N31: =IFERROR(M31/L31-1,1) -> -0.76862683 | O31: =SUM(O32:O35) -> 1550000 | P31: =O31-L31 -> -47000 | Q31: =IFERROR(O31/L31-1,1) -> -0.029430182 | R31: =IF(O31>L31,"เพิ่มขึ้น",IF(O31<L31,"ลดลง",IF(O31=L31,"--"))) -> ลดลง | S31: ปรับกระบวนการ ศอก. ใช้คนตรวจน้อยลงเป็นสำคัญ | T31: - | U31: 0
H32: 1. ศปภ.เยี่ยมครอบครัว | L32: =Dataผลพิปี69!U63 -> 460000 | M32: n.a. | N32: =IFERROR(M32/L32-1,1) -> 1 | O32: ='[18]รวม คชจ.ปี 70'!$C$23 -> 480000 | P32: =O32-L32 -> 20000 | Q32: =IFERROR(O32/L32-1,1) -> 0.043478261 | R32: =IF(O32>L32,"เพิ่มขึ้น",IF(O32<L32,"ลดลง",IF(O32=L32,"--"))) -> เพิ่มขึ้น | S32: 1.มีกลุ่มคนประจำต่างสำนักงานมากขึ้น | T32: - | U32: 0
H33: 2. ผู้บริหาร ศปก. / ศอก. เดินทางไปภูมิภาค /หชป.เวียนงาน | L33: =Dataผลพิปี69!U64 -> 587000 | M33: n.a. | N33: =IFERROR(M33/L33-1,1) -> 1 | O33: ='[18]รวม คชจ.ปี 70'!$C$24 -> 500000 | P33: =O33-L33 -> -87000 | Q33: =IFERROR(O33/L33-1,1) -> -0.14821124 | R33: =IF(O33>L33,"เพิ่มขึ้น",IF(O33<L33,"ลดลง",IF(O33=L33,"--"))) -> ลดลง | S33: 2.ศอก./ศปภ. ใช้คนตรวจน้อยลง / ทริป ผอ. ลดลง | T33: - | U33: 0
H34: 3. ศปภ. โยกย้าย | L34: =Dataผลพิปี69!U65 -> 400000 | M34: n.a. | N34: =IFERROR(M34/L34-1,1) -> 1 | O34: ='[18]รวม คชจ.ปี 70'!$C$25 -> 420000 | P34: =O34-L34 -> 20000 | Q34: =IFERROR(O34/L34-1,1) -> 0.05 | R34: =IF(O34>L34,"เพิ่มขึ้น",IF(O34<L34,"ลดลง",IF(O34=L34,"--"))) -> เพิ่มขึ้น | S34: 3.โยกย้ายมากขึ้น เมื่อหลักเกณฑ์ท้องถิ่นออกปีแรก | T34: - | U34: 0
H35: 4. งานสืบสวนและประมวลข่าว | L35: =Dataผลพิปี69!U66 -> 150000 | M35: n.a. | N35: =IFERROR(M35/L35-1,1) -> 1 | O35: ='[18]รวม คชจ.ปี 70'!$C$26 -> 150000 | P35: =O35-L35 -> 0 | Q35: =IFERROR(O35/L35-1,1) -> 0 | R35: =IF(O35>L35,"เพิ่มขึ้น",IF(O35<L35,"ลดลง",IF(O35=L35,"--"))) -> -- | S35: 4. ตั้งเท่าปีก่อน /เพียงพอใช้ | T35: - | U35: 0
C36: ok | D36: ='สรุปใช้งบ 31กค'!B29 -> 5031107000 | E36: A14 | F36: 14. ค่าธรรมเนียมอื่น ๆ | H36: 1. ค่าความถี่และค่าต่ออายุวิทยุสื่อสาร 2. ใบอนุญาตยุทธภัณฑ์ 3. ค่าตรวจรังสี พนง.รปภ. 7 เครื่อง และ 14 คน 4. ค่าจัดสรรคลื่นความถี่วิทยุ 5. ใบอนุญาตครอบครองเครื่องกำเนิดรังสี | L36: ='สรุปใช้งบ 31กค'!H29 -> 27000 | M36: ='สรุปใช้งบ 31กค'!L29 -> 1177 | N36: =IFERROR(M36/L36-1,1) -> -0.95640741 | O36: ='[19]2570'!$D$28 -> 40000 | P36: =O36-L36 -> 13000 | Q36: =IFERROR(O36/L36-1,1) -> 0.48148148 | R36: =IF(O36>L36,"เพิ่มขึ้น",IF(O36<L36,"ลดลง",IF(O36=L36,"--"))) -> เพิ่มขึ้น | S36: -ค่าธรรมเนียมใหม่ ได้แก่ ค่าบริการ Internet SIM รายปี สำหรับ Body Camara -สำรองฉุกเฉิน | T36: - | U36: 0
B37: มีโปรใช้ร่วมกัน | C37: เช็คโปร? | D37: ='สรุปใช้งบ 31กค'!B32 -> 5031118000 | E37: A15-1 | F37: 15. ค่าสิทธิ์การใช้โปรแกรมส่วนงาน | H37: ใช้โปรแกรม Canva Pro 4 license | L37: ='สรุปใช้งบ 31กค'!H32 -> 6300 | M37: ='สรุปใช้งบ 31กค'!L32 -> 5550 | N37: =IFERROR(M37/L37-1,1) -> -0.11904762 | O37: ='[20]ค่าสิทธิการใช้โปรแกรม ปี 70'!$H$202 -> 8800 | P37: =O37-L37 -> 2500 | Q37: =IFERROR(O37/L37-1,1) -> 0.3968254 | R37: =IF(O37>L37,"เพิ่มขึ้น",IF(O37<L37,"ลดลง",IF(O37=L37,"--"))) -> เพิ่มขึ้น | S37: เพิ่ม 1 licence รวมเป็น 4 licence (ศอก. 2, ศสป. 1, ศปภ. 1) | T37: 4 | U37: ='[20]ค่าสิทธิการใช้โปรแกรม ปี 70'!$I$202 -> 8800
C38: ok | D38: ='สรุปใช้งบ 31กค'!B33 -> 5031133000 | E38: A15-2 | F38: 16. ค่าสิทธิ์การใช้โปรแกรมส่วนกลาง | H38: ใช้โปรแกรม Adobe 1 license | L38: ='สรุปใช้งบ 31กค'!H33 -> 23000 | M38: =L38 -> 23000 | N38: =IFERROR(M38/L38-1,1) -> 0 | O38: ='[21]ค่าสิทธิการใช้โปรแกรม ปี 70'!$H$202 -> 48000 | P38: =O38-L38 -> 25000 | Q38: =IFERROR(O38/L38-1,1) -> 1.0869565 | R38: =IF(O38>L38,"เพิ่มขึ้น",IF(O38<L38,"ลดลง",IF(O38=L38,"--"))) -> เพิ่มขึ้น | S38: เพิ่ม 1 licence รวมเป็น 2 licence (พนง. 1,OS 1) + ราคาปรับตัวเพิ่ม | T38: 1 | U38: ='[21]ค่าสิทธิการใช้โปรแกรม ปี 70'!$I$202 -> 0
C39: ok | D39: ='สรุปใช้งบ 31กค'!B30 -> 5031131000 | E39: A16 | F39: 17. ค่าใช้จ่ายในการสืบสวนเกี่ยวกับงาน รปภ. | H39: ใช้สืบสวนของ ทสส.1-2 | L39: ='สรุปใช้งบ 31กค'!H30 -> 220000 | M39: ='สรุปใช้งบ 31กค'!L30 -> 60000 | N39: =IFERROR(M39/L39-1,1) -> -0.72727273 | O39: ='[22]2570'!$E$7 -> 220000 | P39: =O39-L39 -> 0 | Q39: =IFERROR(O39/L39-1,1) -> 0 | R39: =IF(O39>L39,"เพิ่มขึ้น",IF(O39<L39,"ลดลง",IF(O39=L39,"--"))) -> -- | S39: ตั้งเท่าปีก่อน /เพียงพอใช้ | T39: - | U39: 0
C40: หน่วยงานที่ขอตั้ง | D40: 2. หมวดสินทรัพย์ถาวร | H40: จำนวนปี 69 | I40: ราคา @ ปี 69 | J40: จำนวนปี 70 | K40: ราคา @ ปี 70 | L40: =SUM(L41:L80) -> 29633600 | M40: =SUM(M41:M80) -> 25333985 | N40: =IFERROR(M40/L40-1,1) -> -0.14509256 | O40: =SUM(O41:O80) -> 37441500 | P40: =O40-L40 -> 7807900 | Q40: =IFERROR(O40/L40-1,1) -> 0.26348132 | R40: =IF(O40>L40,"เพิ่มขึ้น",IF(O40<L40,"ลดลง",IF(O40=L40,"--"))) -> เพิ่มขึ้น | U40: =SUM(U41:U80) -> 0
